Workbook
Name Recon1: 'Reconciliation - Main'!$A$6:$E$25
Name Recon2: 'Reconciliation - Main'!$A$30:$F$45
Name SignOff1: 'Sign-Off'!$A$7:$D$14
Name SignOff2: 'Sign-Off'!$A$26:$C$39

Sheet Instructions
B1: Abu Dhabi Clinical Cost Data Collection (ADCCDC)
B6: General Instructions
B7: The Reconciliation Report is an integral part of Abu Dhabi Clinical Cost Data Collection and must be submitted to DOH, by email,
B8: once cost data submission is completed in Shafafiya successfully for the Submission Year 02 (2025)
B10: Facility level:
C11: The template name should be SY2 Annexure Costing Submission Reconciliation Report V1.0A MFXXXX
C12: The subject of the email should be SY2 Annexure Costing Submission Reconciliation Report V1.0A MFXXXX
B13: Group level:
C14: The templae name should be SY2 Annexure Costing Submission Reconciliation Report V1.0A (Group Name)
C15: The subject of the email should be SY2 Annexure Costing Submission Reconciliation Report V1.0A (Group Name)
C16: (please copy the group name from cell B26 of Sign-Off tab. Don’t enter your own value as system will not be able to read these)
B18: Incomplete or faulty Reconciliation Report will not be accepted and this will be considered as non-compliance of the Standards
B20: To make it easier for the providers, we have created check for sign off page only so to ensure that providers fill all the mandatory cells before submission:
B22: Table Name | C22: Title | D22: Check
B23: Sign-Off | C23: Submission Year | D23: =IF(ISNUMBER(FIND("Select",'Sign-Off'!B7)),"WARNING! Submission Year not Selected! Do not Submit to DoH until Revised","Correct")
B24: Sign-Off | C24: Accounting Method | D24: =IF(ISNUMBER(FIND("Select",'Sign-Off'!B8)),"WARNING! Accounting Method not Selected! Do not Submit to DoH until Revised","Correct")
B25: Sign-Off | C25: Overhead Method | D25: =IF(ISNUMBER(FIND("Select",'Sign-Off'!B9)),"WARNING! Overhead Method not Selected! Do not Submit to DoH until Revised","Correct")
B26: Sign-Off | C26: Costing Method | D26: =IF(ISNUMBER(FIND("Select",'Sign-Off'!B10)),"WARNING! Costing Method not Selected! Do not Submit to DoH until Revised","Correct")
B27: Sign-Off | C27: Auditing Status | D27: =IF(ISNUMBER(FIND("Select",'Sign-Off'!B11)),"WARNING! Auditing Status not Selected! Do not Submit to DoH until Revised","Correct")
B28: Sign-Off | C28: Costing Software | D28: =IF(ISNUMBER(FIND("Select",'Sign-Off'!B12)),"WARNING! Costing Software Option not Selected! Do not Submit to DoH until Revised","Correct")
B29: Sign-Off | C29: Costing Software Name | D29: =IF(AND('Sign-Off'!B12="Yes",ISBLANK('Sign-Off'!B13)),"WARNING! Costing Software Option not Selected! Do not Submit to DoH until Revised",IF('Sign-Off'!B12<>"Yes","Ignore","Correct"))
B30: Sign-Off | C30: Reconciliation Level | D30: =IF(ISNUMBER(FIND("Select",'Sign-Off'!B14)),"WARNING! Reconciliation Level Option not Selected! Do not Submit to DoH until Revised","Correct")
B31: Sign-Off | C31: Group | D31: =IF(LOWER('Sign-Off'!B14)="group level", IF(ISNUMBER(SEARCH("select",'Sign-Off'!B26)), "WARNING! Reconciliation Level Option not Selected! Do not Submit to DoH until Revised", "Correct" ), "Ignore" )
B32: Sign-Off | C32: MF + Facility Name | D32: =IF(LOWER('Sign-Off'!B14)="facility level", IF(ISNUMBER(SEARCH("select",'Sign-Off'!B27)), "WARNING! Reconciliation Level Option not Selected! Do not Submit to DoH until Revised", "Correct" ), "Ignore" )
B33: Sign-Off | C33: Signed | D33: =IF(ISBLANK('Sign-Off'!B29), "WARNING! Reconciliation Level Option not Selected! Do not Submit to DoH until Revised", "Correct")
B34: Sign-Off | C34: Position | D34: =IF(ISNUMBER(FIND("Select",'Sign-Off'!B30)),"WARNING! Overhead Method not Selected! Do not Submit to DoH until Revised","Correct")
B36: Please see general instructions for all other tabs of the Reconciliation Report
B38: Table Name | C38: Purpose | D38: Status
B39: Reconciliation - Main | C39: To capture the summary of all the relevant expenses | D39: Mandatory to fill the designated cells by all providers
B40: Inclusions - GL | C40: These are expenses which are not recorded in GL and need to be inlcuded | D40: Mandatory to fill for the providers having these type of expenses
B41: Exclusions - GL | C41: These are expenses which are recorded in GL but need to be excluded from costing as they are not applicable | D41: Mandatory to fill for the providers having these type of expenses
B42: EncountersData | C42: To capture the Shafafiya submission by facility by patient type by volume with direct and overhead cost breakdown | D42: Mandatory for All providers to fill this table
B43: WIP | C43: To educate the providers on how to report WIP based on their category | D43: Education for WIP Submission
B44: DataValidations | C44: To provide with list of validations to providers to run these internally before submitting the cost data to ensure accuracy of the submission | D44: Mandatory for All providers to fill this table

Sheet Sign-Off
A1: #VALUE! | B1: Abu Dhabi Clinical Cost Data Collection (ADCCDC)
B3: Sign off by the Competent Authority with Facility / Group
B4: The reconciliation report (email) accompanying the cost data (Shafafiya) is encouraged to be submitted at the same date.
B5: The submission period will be from 1st to 31st August 2026.
A7: Submission Year : | B7: SY-02-2025 | D7: =VLOOKUP(B7,References!B3:C7,2,FALSE)
A8: Accounting Method: | B8: Accrual Accounting | D8: =VLOOKUP(B8,References!B9:C12,2,FALSE)
A9: Overhead Method: | B9: Step-Down Method | D9: =VLOOKUP(B9,References!B15:C17,2,FALSE)
A10: Costing Method: | B10: Hybrid Costing (ABC and Top-Down) | D10: =VLOOKUP(B10,References!B20:C23,2,FALSE)
A11: Auditing Status | B11: External Audit Completed | D11: =VLOOKUP(B11,References!B26:C28,2,FALSE)
A12: Costing Software | B12: Yes | D12: =VLOOKUP(B12,References!B31:C33,2,FALSE)
A13: Costing Vendor Name | B13: Mysmyle Clinical Costing Module | D13: Enter manually
A14: Reconciliation Level | B14: Facility Level | D14: =VLOOKUP(B14,References!B37:C39,2,FALSE)
A16: Directors' Attestation
A17: To the best of my knowledge, the clinical costing data reconciliation report for the Abu Dhabi Clinical Cost Data Collection for the mentioned below health facility:
A18: 1 | B18: Complies with the Abu Dhabi Clinical Costing Standards and Abu Dhabi Clinical Costing Guidelines V2.0;
A19: 2 | B19: Complies with the Abu Dhabi Clinical Cost Data Collection reporting requirements;
A20: 3 | B20: Gives a true and fair view of the health facility's expenses for the targeted costing exercise year to determine patient-level costs;
A21: 4 | B21: Accurately represents the patient level cost data submitted to the department for the ADCCDC collection;
A22: 5 | B22: The data entered into the following templates represents the data used for the relevant submission year of the final ADCCDC collection; and
A23: 6 | B23: The costing data submitted is for all final patient products, whether they are from self-pay, sponsored encounters, or insured patients.
A26: Group | B26: Select Group
A27: MF + Facility Name | B27: MF4159 - VISION DENTAL CLINIC L.L.C | D27: Not applicable if you selected "Group" for Reconciliation Level
A29: Signed | B29: Heba Hamdy Abdel Rahman
A30: Position | B30: Chief Executive Officer (CEO)
A31: Date | B31: 46322
A32: Phone | B32: (971)505749749
A33: Work Email | B33: management@visiondentalclinic.com
A35: Prepared | B35: Mohamed Abdel Moniem Mohamed
A36: Position | B36: Accountant
A37: Date | B37: 46322
A38: Phone | B38: (971)509105033
A39: Work Email | B39: accounts@visiondentalclinic.com

Sheet References
B2: Submission Year
B3: Select Submission Year | C3: Select Submission Year
B4: SY-01-2024 | C4: Financial Year 2024
B5: SY-02-2025 | C5: Financial Year 2025
B6: SY-03-2026 | C6: Financial Year 2026
B7: SY-04-2027 | C7: Financial Year 2027
B9: Select Accounting Method | C9: Select Accounting Method
B10: Accrual Accounting | C10: Recognizes revenue and expenses when they are earned or incurred, typically at cost centre level, regardless of cash transactions.
B11: Cash Accounting | C11: Records revenue and expenses solely based on cash flow, without departmental tracking.
B12: Other (please specify) | C12: Allows for the selection of any other accounting method not listed above. Please provide the method used (column I).
B15: Select OH Allocation Method | C15: Select OH Allocation Method
B16: Step-Down Method | C16: This method allocates overhead costs exclusively to direct cost centers. Overhead cost centers will not receive any overhead cost allocations, even if they consume each other's activities. This approach is less accurate.
B17: Reciprocal Method | C17: This method uses simultaneous equations to allocate overhead costs, accounting also for mutual activities provided among departments. It results in a more accurate cost distribution across both overhead and direct cost centers.
... B33: No | C33: If you have used internal applications such as Ms Excel
B34: Costing Vendor Name
B37: Select Option | C37: Select Option
B38: Group Level | C38: If you will submit one Reconciliation Report for all group facilities
B39: Facility Level | C39: In case you will submit separate Reconciliation Reports for each facility
B41: Select Option
B42: Chief Executive Officer (CEO)
B43: Chief Financial Officer (CFO)
B44: Finance Director
B46: WIP Drop Down
B47: YES
B48: NO
B50: Patient Type
B51: 1-No Bed + No Emergency
B52: 2-No Bed + Emergency
B53: 3-Inpatient + No Emergency
B54: 4-Inpatient + Emergency
... B3756: HEALTH TIME MEDICAL CENTRE
B3757: 0
B3758: PRIORY HEALTHCARE L.L.C
B3759: Prestige Pharmacy
B3760: American Crescent Health Care Centre
B3761: Cambridge Medical & Rehabilitation (Group)
B3762: Medcart Pharmacy L.L.C Branch
B3763: American Dental Centre
B3764: MUNICH MEDICAL AND REHABILITION CENTER LLC (Group)
B3765: Manchester Dental and American Cosmetic (Group)
...

Sheet Reconciliation - Main
A1: #VALUE! | B1: Abu Dhabi Clinical Costing Data Collection Main Reconciliation Page
A6: Step 1 - Annual Financial Statements | C6: Financial Statement
A7: Obtain the final total expenditure as reported in the annual financial statement (AFS) for the Submission Year | C7: Total expenses as reported in annual financial statements for the financial year | E7: 6453402
A9: Step 2 - General Ledger Expenses | C9: General Ledger Expenses
A10: The General Ledger data provided by the Finance system for costing purposes should reconcile to cell C8. | C10: Total expenses as reported in general ledger for the financial year | E10: 6453402
A12: Reconciliation (Step 1 - Step 2) | C12: If there is difference between AFS and GL, please list down | E12: =E7-E10
A17: Step 3 - Adjustments for Costing | C17: Adjustments made in GL prior to Costing
A18: Expenses removed or included from the finance GL extract for the purposes of creating a "cost ledger" are to be detailed here to demonstrate the reconciliation to source (in Step 1). | C18: Step 3.1 - Inclusions (please provide details in Inclusions tab) | E18: ='Inclusions - General Ledger'!B4
C19: Step 3.2 - Exclusions (please provide details in Exclusions tab) | E19: ='Exclusions - General Ledger'!B4
A21: Step 4. Costing GL | C21: Total Cost Ledger Expenses post Inclusions and Exclusions
A22: The Costing GL takes into consideration any adjustments made to the Finance GL (outlined in Step 3). This now shows the expenses to be allocated for costing purposes. | C22: Total Operating Expenses = Step 2 +3.1-3.2 | E22: =+E10+E18-E19
A24: Reconciliation = Step 2 - (Step 4 + 3.1 - 3.2) | C24: Reconciliation of GL to Costing GL (taking into account exclusions and inclusions)
C25: If there is a variance between Finance GL and Costing GL please detail below | E25: =+E10-(E22+E19-E18)
A30: Step 6. | C30: Total Costed Configuration (Post Cost Allocation)
A31: This is a summary table where the configuration represents the final costs that has been allocated to patients. There is no need to populate this step as these columns will self populate. Any exclusions/inclusions incorporated prior to submission are to be detailed below in Step 7. | C31: Total Costs (Current Year) | E31: Overhead | F31: Direct
E32: 2124656.6 | F32: 4328745.4
C33: Total Costs (Current Year Costed, as per Step 4) | E33: =SUM(E32:E32) | F33: =SUM(F32:F32)
A35: Step 7. | C35: Exclusions and Inclusions (including Work In Progress) that impact the ADCCDC Submission
A36: This step details all costs that are excluded and/or included for submission to the ADCCDC collection. | C36: 7.1 Excluded Costs (please detail) | E36: Overhead | F36: Direct | G36: Total
C37: Non Patient Products | E37: 0 | F37: 0 | G37: =SUM(E37:F37)
C38: WIP | E38: 0 | F38: 0 | G38: =SUM(E38:F38)
C39: Others if any | E39: 0 | F39: 0 | G39: =SUM(E39:F39)
C40: Total Excluded Costs | E40: =SUM(E37:E39) | F40: =SUM(F37:F39) | G40: =SUM(G37:G39)
C42: 7.2 Additional (or Included) Costs (please detail) | E42: Overhead | F42: Direct | G42: Total
A43: Please report the WIP cost and any other applicable cost | C43: WIP | E43: 0 | F43: 0 | G43: 0
C44: Others if any | E44: 0 | F44: 0 | G44: 0
C45: Total Included Costs | E45: =SUM(E43:E44) | F45: =SUM(F43:F44) | G45: =SUM(G43:G44)
A47: Step 8. | C47: Final Submission to ADCCDC | E47: Overhead | F47: Direct | G47: Total
A48: This configuration represents the final costs that will be submitted to the ADCCDC collection. | C48: 6. Total Costs as per Current Year Costed | E48: =E33 | F48: =F33 | G48: =SUM(E48:F48)
C49: 7.1. Less Excluded Costs | E49: =-E40 | F49: =-F40 | G49: =SUM(E49:F49)
C50: 7.2. Add Included Costs | E50: =E45 | F50: =F45 | G50: =SUM(E50:F50)
C51: Total Costs submitted to ADCCDC | E51: =SUM(E48:E50) | F51: =SUM(F48:F50) | G51: =SUM(G48:G50) | H51: This should match the total value in your SY2 ADCCDC submission in Shafafiya.
A52: Key Notes:
B53: Providers are only allowed to edit these cells
B55: Providers are not allowed to edit these cells
B57: Providers are not allowed to edit these cells

Sheet Inclusions - General Ledger
A1: Abu Dhabi Clinical Costing Data Collection - Inclusions - General Ledger | C1: #VALUE!
A2: 1. Example Inclusions are provided for guidance purposes only.
A3: 2. Amend or add lines as required
A4: Control Total | B4: =SUM(Inclusions[Amount])
A5: Included | B5: Amount | C5: Details
A6: Third Party Expenses - Central corporate office /shared services | B6: 0
A7: Offsets and Recoveries | B7: 0
A8: Prior Year Adjustments | B8: 0
A9: Shared Service | B9: 0
A10: Outsourced Services | B10: 0
A11: Temp staff/invoices/contracted staff | B11: 0
A12: Insurance for staff (health and life etc.) | B12: 0
A13: Training (ONLY for patient SLR delivery) - if not recorded in GL already | B13: 0
A14: Adjustments and Offsets (e.g. error corrections, recoveries, secondments) | B14: 0

Sheet Exclusions - General Ledger
A1: Abu Dhabi Clinical Costing Data Collection - Exclusions - General Ledger | C1: #VALUE!
A2: 1. Example Exclusions are provided for guidance purposes only.
A3: 2. Amend or add lines as required
A4: Control Total | B4: =SUM(Exclusions[Amount])
A5: Excluded | B5: Amount | C5: Details
A6: Bad Debts | B6: 0
A7: Offsets / Recoveries | B7: 0
A8: Prior Year Adjustments | B8: 0
A9: Cost of Raising Capital | B9: 0
A10: Dividends | B10: 0
A11: Volume Discounts | B11: 0
A12: Donations | B12: 0
A13: Research | B13: 0
A14: Education and Training | B14: 0

Sheet EncountersData
A1: Abu Dhabi Clinical Costing Data Collection - Facility Level Encounter and Costing Details | G1: #VALUE!
A2: 1. If you are providing one consolidated reconciliation for the whole group then list down facilities in Column A
A3: 2. List the encounter types in Column B and enter volumes in Column C
A4: 3. Provice cost breakdown in Column D and E
C5: =SUM(EncLoaded[Volumes]) | D5: =SUM(EncLoaded[Direct Cost]) | E5: =SUM(EncLoaded[Overhead Cost]) | F5: =SUM(EncLoaded[Total Cost])
A6: MF Number & Facility Name | B6: Encounter Type | C6: Volumes | D6: Direct Cost | E6: Overhead Cost | F6: Total Cost | G6: Average Total Cost
A7: MF4159 - VISION DENTAL CLINIC L.L.C | B7: 1-No Bed + No Emergency | C7: 9738 | D7: 4328745.4 | E7: 2124656.6 | F7: =SUM(EncLoaded[[#This Row],[Direct Cost]:[Overhead Cost]]) | G7: =EncLoaded[[#This Row],[Total Cost]]/EncLoaded[[#This Row],[Volumes]]
A8: Select Facility | B8: Select Encounter Type | F8: =SUM(EncLoaded[[#This Row],[Direct Cost]:[Overhead Cost]]) | G8: =EncLoaded[[#This Row],[Total Cost]]/EncLoaded[[#This Row],[Volumes]]
A9: Select Facility | B9: Select Encounter Type | F9: =SUM(EncLoaded[[#This Row],[Direct Cost]:[Overhead Cost]]) | G9: =EncLoaded[[#This Row],[Total Cost]]/EncLoaded[[#This Row],[Volumes]]
A10: Select Facility | B10: Select Encounter Type | F10: =SUM(EncLoaded[[#This Row],[Direct Cost]:[Overhead Cost]]) | G10: =EncLoaded[[#This Row],[Total Cost]]/EncLoaded[[#This Row],[Volumes]]
A11: Select Facility | B11: Select Encounter Type | F11: =SUM(EncLoaded[[#This Row],[Direct Cost]:[Overhead Cost]]) | G11: =EncLoaded[[#This Row],[Total Cost]]/EncLoaded[[#This Row],[Volumes]]
A12: Select Facility | B12: Select Encounter Type | F12: =SUM(EncLoaded[[#This Row],[Direct Cost]:[Overhead Cost]]) | G12: =EncLoaded[[#This Row],[Total Cost]]/EncLoaded[[#This Row],[Volumes]]
A13: Select Facility | B13: Select Encounter Type | F13: =SUM(EncLoaded[[#This Row],[Direct Cost]:[Overhead Cost]]) | G13: =EncLoaded[[#This Row],[Total Cost]]/EncLoaded[[#This Row],[Volumes]]
A14: Select Facility | B14: Select Encounter Type | F14: =SUM(EncLoaded[[#This Row],[Direct Cost]:[Overhead Cost]]) | G14: =EncLoaded[[#This Row],[Total Cost]]/EncLoaded[[#This Row],[Volumes]]
A15: Select Facility | B15: Select Encounter Type | F15: =SUM(EncLoaded[[#This Row],[Direct Cost]:[Overhead Cost]]) | G15: =EncLoaded[[#This Row],[Total Cost]]/EncLoaded[[#This Row],[Volumes]]
A16: Select Facility | B16: Select Encounter Type | F16: =SUM(EncLoaded[[#This Row],[Direct Cost]:[Overhead Cost]]) | G16: =EncLoaded[[#This Row],[Total Cost]]/EncLoaded[[#This Row],[Volumes]]
A17: Select Facility | B17: Select Encounter Type | F17: =SUM(EncLoaded[[#This Row],[Direct Cost]:[Overhead Cost]]) | G17: =EncLoaded[[#This Row],[Total Cost]]/EncLoaded[[#This Row],[Volumes]]
A18: Select Facility | B18: Select Encounter Type | F18: =SUM(EncLoaded[[#This Row],[Direct Cost]:[Overhead Cost]]) | G18: =EncLoaded[[#This Row],[Total Cost]]/EncLoaded[[#This Row],[Volumes]]
A19: Select Facility | B19: Select Encounter Type | F19: =SUM(EncLoaded[[#This Row],[Direct Cost]:[Overhead Cost]]) | G19: =EncLoaded[[#This Row],[Total Cost]]/EncLoaded[[#This Row],[Volumes]]
... A111: Select Facility | B111: Select Encounter Type | F111: =SUM(EncLoaded[[#This Row],[Direct Cost]:[Overhead Cost]]) | G111: =EncLoaded[[#This Row],[Total Cost]]/EncLoaded[[#This Row],[Volumes]]

Sheet WIP
G1: #VALUE!
A3: Abu Dhabi Clinical Costing Data Collection - Work in Progress Reporting
A9: Category | B9: Reporting Instruction | C9: Report in Shafafiya | D9: Report in Reconciliation (WIP) | E9: Previous Year | F9: Present Year (Submission Year) | G9: Future Year
A10: Patient admitted in Previous Year and discharged in Submission Year) | B10: Full Patient Cost (Previous Year and Submission Year) will be reported against costing outputs in Shafafiya for Submission Year. Previous Year carried forward cost will also be reporting in the Main tab of Reconciliation and added as reconciling item under 7.2 | C10: YES | D10: YES
A11: Patient admitted in Previous Year but was not discharged in Submission Year) | B11: Full patient cost will not be reported against costing outputs in Shafafiya since the patient is not discharged on the last day of Submission Year. The patient cost related to Submission Year will be reported in the main tab of Reconciliation Report under 7.1 | C11: NO | D11: YES
A12: Patient admitted and discharged in Submission Year | B12: Full patient cost will be reported against the costing outputs in Shafafiya for Submission Year | C12: YES | D12: NO
A13: Patient admitted in Submission Year but discharged in Future Year | B13: The patient cost will not be reported against costing ouputs in Shafafiya for the Submission Year. The patient cost related to Submission Year will be reported in the Reconciliation Report under 7.1 | C13: NO | D13: YES

Sheet DataValidations
A1: #VALUE! | B1: Abu Dhabi Clinical Costing Data Collection - Data Validations
B3: Note: These validations are non-exhaustive and directional. Cost accountants should use their judgment, expertise, and analytical skills to ensure data accuracy.
B4: 1. You must check the box of one of the following columns for each Data Validation Line itemised in the below table:
B5: 2. Validated: Check this box for each of the validations performed and successfully passed.
B6: 3. Does Not Apply: Check this box only if the Encounter Type listed is does not apply to your Group or Facility
B7: 3. No Issues Detected Checklist: Check this box if there were validations issues, but it was determined they were not detrimental to the quality of the data. In the case of genuine outliers in the data, you can report no issue, however a brief explanation of should be provided in the Comments column (L)
B8: 4. With Issues Detected : Tick this box if there are issues in the data as per validations and tolerance. Provide Commentary as necessary or
B9: 5. Issues Resolved : Tick this box if a previous issue was identified and is now resolved. Provide brief commentary itemising the issue and action taken.
A12: Patient Type | B12: Encounter Type | C12: Description | D12: Validations | E12: Tolerance | F12: Non-Compliance | G12: Validated | H12: Does Not Apply | I12: No Issues Detected | J12: With Issues | K12: Issues Resolved | L12: Comments
A13: All Patient Types | B13: All Encounter Types | C13: Zero / Negative Cost | D13: Identify zero or negative cost at the encounter / claim level | E13: Total encounter / claim cost is = < 0 Dhs | F13: Rejection | G13: TRUE | H13: FALSE | I13: TRUE | J13: FALSE | K13: FALSE | L13: 9,738 claims in the twelve files; no zero or negative encounter (internal validator run on every file).
A14: All Patient Types | B14: All Encounter Types | C14: Cost Bucket Total mismatch Cost Type Total | D14: Where total of cost buckets (direct and overhead) does not match to total of cost types (direct and overheads) | F14: Rejection | G14: TRUE | H14: FALSE | I14: TRUE | J14: FALSE | K14: FALSE | L14: Cost bucket total = cost type total on 9,738 of 9,738 claims, both views 6,453,401.98. This was the cause of the 9 Oct 2026 rejection; corrected in this resubmission.
A15: Emergency | B15: 2-No Bed + Emergency | C15: No Physician Cost Type | D15: Identify emergency encounters / claims without physician costs | F15: Warning | G15: FALSE | H15: TRUE | I15: FALSE | J15: FALSE | K15: FALSE | L15: Stand-alone outpatient dental clinic: no emergency, inpatient, day-case or home-care encounters.
A16: Emergency | B16: 2-No Bed + Emergency | C16: No ED Cost | D16: Identify emergency department encounters / claims with no associated costs | F16: Warning | G16: FALSE | H16: TRUE | I16: FALSE | J16: FALSE | K16: FALSE | L16: Stand-alone outpatient dental clinic: no emergency, inpatient, day-case or home-care encounters.
A17: Inpatient | B17: 4-Inpatient + Emergency & 3-Inpatient + No Emergency | C17: Low LOS Costs | D17: Identify low cost for IP encounter / claim | E17: Where LOS = Multiday and total encounter / claim costs less than 5000 Dhs by encounter / claim | F17: Warning | G17: FALSE | H17: TRUE | I17: FALSE | J17: FALSE | K17: FALSE | L17: Stand-alone outpatient dental clinic: no emergency, inpatient, day-case or home-care encounters.
A18: Inpatient | B18: 4-Inpatient + Emergency & 3-Inpatient + No Emergency | C18: High Costs | D18: Identify total high-cost encounters / claims (excluded LTC type) | E18: Total encounter / claim cost is > 500,000 Dhs by encounter / claim | F18: Warning | G18: FALSE | H18: TRUE | I18: FALSE | J18: FALSE | K18: FALSE | L18: Stand-alone outpatient dental clinic: no emergency, inpatient, day-case or home-care encounters.
A19: Inpatient | B19: 4-Inpatient + Emergency & 3-Inpatient + No Emergency | C19: Theatre Attendance Flag but no Procedure time | D19: Identify encounters / claims where Theatre Attendance flag is "yes" but no procedure time is reported | F19: Warning | G19: FALSE | H19: TRUE | I19: FALSE | J19: FALSE | K19: FALSE | L19: Stand-alone outpatient dental clinic: no emergency, inpatient, day-case or home-care encounters.
A20: Inpatient | B20: 4-Inpatient + Emergency & 3-Inpatient + No Emergency | C20: Theatre Attendance Flag but not OR or SPS cost | D20: Identify encounters / claims where Theatre Attendance flag is "yes" but no OR or SPS cost is reported | F20: Warning | G20: FALSE | H20: TRUE | I20: FALSE | J20: FALSE | K20: FALSE | L20: Stand-alone outpatient dental clinic: no emergency, inpatient, day-case or home-care encounters.
A21: Inpatient | B21: 4-Inpatient + Emergency & 3-Inpatient + No Emergency | C21: Surgical DRG No OR Cost | D21: Identify encounters / claims with surgical DRGs with no Operating Room or Special Procedure Suites cost | E21: Where encounters / claim are grouped to surgical DRGs but OR and SPS cost buckets have zero cost | F21: Warning | G21: FALSE | H21: TRUE | I21: FALSE | J21: FALSE | K21: FALSE | L21: Stand-alone outpatient dental clinic: no emergency, inpatient, day-case or home-care encounters.
A22: Inpatient | B22: 4-Inpatient + Emergency & 3-Inpatient + No Emergency | C22: Prostheses DRG No Cost | D22: Identify encounters / claims in DRGs with expected prostheses consumption but no prosthesis cost | E22: Where encounters / claim are grouped to DRGs with expected prosthesis consumption, but the prosthesis cost bucket has zero cost | F22: Warning | G22: FALSE | H22: TRUE | I22: FALSE | J22: FALSE | K22: FALSE | L22: Stand-alone outpatient dental clinic: no emergency, inpatient, day-case or home-care encounters.
A23: Inpatient | B23: 4-Inpatient + Emergency & 3-Inpatient + No Emergency | C23: No Ward / HDU Cost | D23: Identify inpatient encounters / claims without Ward / ICU costs | E23: Encounter IP with ward / ICU cost = 0 Dhs | F23: Warning | G23: FALSE | H23: TRUE | I23: FALSE | J23: FALSE | K23: FALSE | L23: Stand-alone outpatient dental clinic: no emergency, inpatient, day-case or home-care encounters.
A24: Inpatient | B24: 4-Inpatient + Emergency & 3-Inpatient + No Emergency | C24: No Physician Cost bucket | D24: Identify inpatient encounters / claims where physician costs are missing | F24: Warning | G24: FALSE | H24: TRUE | I24: FALSE | J24: FALSE | K24: FALSE | L24: Stand-alone outpatient dental clinic: no emergency, inpatient, day-case or home-care encounters.
A25: Inpatient | B25: 4-Inpatient + Emergency & 3-Inpatient + No Emergency | C25: No Pharmacy Cost | D25: Identify inpatient encounters / claims with no pharmacy costs | F25: Warning | G25: FALSE | H25: TRUE | I25: FALSE | J25: FALSE | K25: FALSE | L25: Stand-alone outpatient dental clinic: no emergency, inpatient, day-case or home-care encounters.
A26: Inpatient | B26: 4-Inpatient + Emergency & 3-Inpatient + No Emergency | C26: No Laboratory Cost | D26: Identify inpatient encounters / claims without laboratory costs | F26: Warning | G26: FALSE | H26: TRUE | I26: FALSE | J26: FALSE | K26: FALSE | L26: Stand-alone outpatient dental clinic: no emergency, inpatient, day-case or home-care encounters.
A27: Inpatient | B27: 4-Inpatient + Emergency & 3-Inpatient + No Emergency | C27: OR Cost But No Anaesthesia Cost | D27: Identify encounters / claims with OR cost but no Anaesthesia cost | F27: Warning | G27: FALSE | H27: TRUE | I27: FALSE | J27: FALSE | K27: FALSE | L27: Stand-alone outpatient dental clinic: no emergency, inpatient, day-case or home-care encounters.
A28: Outpatient | B28: 1-No Bed + No Emergency | C28: High OP Costs | D28: Identify non admitted encounters / claims with high total costs for OP attendances | E28: Total encounter / claim cost is > 5,000 Dhs | F28: Warning | G28: TRUE | H28: FALSE | I28: TRUE | J28: FALSE | K28: FALSE | L28: 218 claims above 5,000 AED: implant, bone-graft, full-arch and multi-crown prosthodontic cases; prostheses at actual stock cost. Reviewed, genuine.
A29: Outpatient | B29: 1-No Bed + No Emergency | C29: Low OP Costs | D29: Identify non admitted encounters / claims with low total costs for OP attendances | E29: Total encounter / claim cost is < 50 Dhs | F29: Warning | G29: TRUE | H29: FALSE | I29: TRUE | J29: FALSE | K29: FALSE | L29: 1,152 claims below 50 AED: single low-fee attendances (consultations, reviews, simple procedures) costed from the CPT allocation table. Reviewed, genuine; table prices noted for SY03.
A30: Outpatient | B30: 1-No Bed + No Emergency | C30: Unexpected Clinic Costs | D30: Identify non admitted clinic encounters / claims with unexpected costs | E30: Identify where ICU, OR, SPS, ED cost buckets have cost against these encounters / claim | F30: Warning | G30: TRUE | H30: FALSE | I30: TRUE | J30: FALSE | K30: FALSE | L30: 0 claims carry ICU, OR, SPS or ED cost. Buckets used: Dental, Anaesthesia, Imaging, Prosthesis.
A31: Outpatient | B31: 5-Day Case + No Emergency & 6-Day Case + Emergency | C31: High Day Procedure Costs | D31: Identify non admitted procedure encounters / claims with high costs | E31: Total encounter / claim costs is > 25,000 Dhs | F31: Warning | G31: FALSE | H31: TRUE | I31: FALSE | J31: FALSE | K31: FALSE | L31: Stand-alone outpatient dental clinic: no emergency, inpatient, day-case or home-care encounters.
A32: Outpatient | B32: 5-Day Case + No Emergency & 6-Day Case + Emergency | C32: Low Day Procedure Costs | D32: Identify non admitted procedure encounters / claims with low costs | E32: Total encounter / claim costs is <500 Dhs | F32: Warning | G32: FALSE | H32: TRUE | I32: FALSE | J32: FALSE | K32: FALSE | L32: Stand-alone outpatient dental clinic: no emergency, inpatient, day-case or home-care encounters.
A33: Home Care | B33: 12-Home Care | C33: High Cost | D33: Identify encounters / claims with high costs | E33: Total encounter / claim costs is > 25,000 Dhs | F33: Warning | G33: FALSE | H33: TRUE | I33: FALSE | J33: FALSE | K33: FALSE | L33: Stand-alone outpatient dental clinic: no emergency, inpatient, day-case or home-care encounters.
A34: Home Care | B34: 12-Home Care | C34: Low Cost | D34: Identify encounters / claims with low costs | E34: Total encounter / claim costs is <50 Dhs | F34: Warning | G34: FALSE | H34: TRUE | I34: FALSE | J34: FALSE | K34: FALSE | L34: Stand-alone outpatient dental clinic: no emergency, inpatient, day-case or home-care encounters.
A35: Home Care | B35: 12-Home Care | C35: Unexpected Costs | D35: Identify encounters / claims /bundles with unexpected costs | E35: Identify where Ward, ICU, OR, SPS, ED cost buckets have cost against these encounters / claim | F35: Warning | G35: FALSE | H35: TRUE | I35: FALSE | J35: FALSE | K35: FALSE | L35: Stand-alone outpatient dental clinic: no emergency, inpatient, day-case or home-care encounters.
