Workbook

Sheet Vision
B2: Vision Dental Clinic
B3: Financial Report for the year Jan 2025
B4: Profit & Loss Statement
B5: Casflow Statement
D7: Profit & Loss Statement | E7: Amount | H7: %age | I7: Collection | J7: Coll % | P7: Cashflow Statement | Q7: Ref. | R7: Amount | U7: %age | X7: Differences (P&L - CF)
B8: Sales / Income: | N8: Current Period Collection:
C9: =+Sales!A7 -> Dr. Hussien Tahoun | O9: Cash & Cheque Collection of Jan 2025 | R9: =+Collection!T16 -> 9710.17 | U9: =R9/$R$25 -> 0.039780193
D10: Cash & Credit Card of Jan 2025 - (a) | E10: =+Sales!D9 -> 21054.26 | H10: =E10/$E$47 -> 0.05284223 | I10: =+Sales!H86 -> 37920.09 | J10: =+I10/E10 -> 1.801065 | O10: Credit Card Jan 2025 | R10: =+'Bank Recon'!E231 -> 194833.18 | U10: =R10/$R$25 -> 0.79818391
D11: Insurance Sales of Jan 2025 - (b) | E11: =+Sales!D17 -> 44043.4 | H11: =E11/$E$47 -> 0.11054064 | O11: Tabby, Bank Trf & Others | R11: =+Collection!M21 -> 815 | U11: =R11/$R$25 -> 0.0033388558
E12: =SUM(E10:E11) -> 65097.66 | H12: =SUM(H10:H11) -> 0.16338287 | I12: =SUM(I10:I11) -> 37920.09
O13: Total Current period Self Pay Sales Collection | Q13: (a) | R13: =R9+R10+R11 -> 205358.35 | U13: =SUM(U9:U12) -> 0.84130296
C14: =+Sales!A21 -> Dr. Salim Alhamadani | O14: Cash Collection but not deposited in bank | R14: 0
D15: Cash & Credit Card of Jan 2025 - (c) | E15: =+Sales!D23 -> 27524.4 | H15: =E15/$E$47 -> 0.069081064 | I15: =+Sales!H101 -> 18228.77 | J15: =+I15/E15 -> 0.66227674 | O15: Insurance Collection for the Year | R15: =+'Claim Sheet'!J16 -> 38737.25 | U15: =R15/$R$25 -> 0.15869704
D16: Insurance Sales of Jan 2025 - (d) | E16: =+Sales!D32 -> 53387.66 | H16: =E16/$E$47 -> 0.13399298
E17: =SUM(E15:E16) -> 80912.06 | H17: =SUM(H15:H16) -> 0.20307404 | I17: =SUM(I15:I16) -> 18228.77 | O17: Total Previous month Sales Collection | Q17: (b) | R17: =SUM(R14:R15) -> 38737.25 | U17: =SUM(U13:U15) -> 1
C19: =+Sales!A36 -> Dr. Asma Butt
D20: Cash & Credit Card of Jan 2025 - (e) | E20: =+Sales!D38 -> 30110.9 | H20: =E20/$E$47 -> 0.075572692 | I20: =+Sales!H78 -> 29434.62 | J20: =+I20/E20 -> 0.97754036
D21: Insurance Sales of Jan 2025 - (f) | E21: =+Sales!D47 -> 51530.26 | H21: =E21/$E$47 -> 0.12933125 | O21: Grand Total of Sales Collection | Q21: (c = a+b) | R21: =R17+R13 -> 244095.6 | U21: =R21/$R$25 -> 1
E22: =SUM(E20:E21) -> 81641.16 | H22: =SUM(H20:H21) -> 0.20490395 | I22: =SUM(I20:I21) -> 29434.62 | O22: Collection from Vending Machine | Q22: (d) | R22: 0 | U22: =R22/$R$25 -> 0
O23: Other Refunds | Q23: (e) | R23: 0 | U23: =R23/$R$25 -> 0
C24: =+Sales!A51 -> Dr. Amr Labib | O24: Loan Fund | Q24: (f) | R24: 0 | U24: =R24/$R$25 -> 0
D25: Cash & Credit Card of Jan 2025 - (e) | E25: =+Sales!D52 -> 1723.98 | H25: =E25/$E$47 -> 0.0043268653 | I25: =+Sales!H72 -> 13772.98 | J25: =+I25/E25 -> 7.9890602 | O25: Total Collection Received | Q25: (g= c+d+e+f) | R25: =R21+R22+R23+R24 -> 244095.6 | U25: =U21+U22+U23+U24 -> 1
D26: Insurance Sales of Jan 2025 - (f) | E26: =+Sales!D62 -> 2756 | H26: =E26/$E$47 -> 0.0069170413
E27: =SUM(E25:E26) -> 4479.98 | H27: =SUM(H25:H26) -> 0.011243907 | I27: =SUM(I25:I26) -> 13772.98
C29: =+Sales!A67 -> Dr. Ammar
D30: Cash & Credit Card of Jan 2025 - (e) | E30: =+Sales!D69 -> 20773.99 | H30: =E30/$E$47 -> 0.052138805 | I30: =+Sales!H64 -> 12470.83 | J30: =+I30/E30 -> 0.60030981
D31: Insurance Sales of Jan 2025 - (f) | E31: =+Sales!D78 -> 107379.65 | H31: =E31/$E$47 -> 0.26950271
E32: =SUM(E30:E31) -> 128153.64 | H32: =SUM(H30:H31) -> 0.32164152 | I32: =SUM(I30:I31) -> 12470.83
C34: =+Sales!A85 -> Dr. Ibrahim
D35: Cash & Credit Card of Jan 2025 - (e) | E35: =+Sales!D87 -> 18013.22 | H35: =E35/$E$47 -> 0.045209792 | I35: =+Sales!H94 -> 12406.26 | J35: =+I35/E35 -> 0.68873083
D36: Insurance Sales of Jan 2025 - (f) | E36: =+Sales!D96 -> 20138.53 | H36: =E36/$E$47 -> 0.05054392
E37: =SUM(E35:E36) -> 38151.75 | H37: =SUM(H35:H36) -> 0.095753712 | I37: =SUM(I35:I36) -> 12406.26
C40: Other Income
D41: External LAB | E41: 0
C43: Total
D44: Cash & Credit Card of Jan 2025 - (i = a+c+e+g) | E44: =E10+E15+E20+E30+E25+E35 -> 119200.75 | H44: =E44/$E$47 -> 0.29917145 | I44: =I12+I17+I22+I32+I27+I37 -> 124233.55 | J44: =+I44/E44 -> 1.0422212
D45: Insurance Sales of Jan 2025 - (j = b+d+f+h) | E45: =E11+E16+E21+E31+E26+E36 -> 279235.5 | H45: =E45/$E$47 -> 0.70082855 | I45: 0
D46: Other Income | E46: 0 | H46: =E46/$E$47 -> 0
E47: =SUM(E44:E46) -> 398436.25 | H47: =SUM(H44:H46) -> 1 | I47: =SUM(I44:I46) -> 124233.55 | J47: =+I47/E44 -> 1.0422212
X48: =-E47+R25 -> -154340.65
...

Sheet Pivot cash in hand
A1: Row Labels | B1: Sum of Amount
A2: 01- Equipment and Supply | B2: 79330.67
A3: 01- Consumables / New Invoice Payment | B3: 4948.97
A4: 02- Consumables / Old Invoice Payment | B4: 57892.7
A5: 03- Fixed Asset Purchase | B5: 13619
A6: 05- External Lab / New Invoice Payment | B6: 1470
A7: 04- Equipments Maintenance | B7: 1000
A8: 06- External Lab / Old Invoice Payment | B8: 400
A9: 02- General Running and Maintenance | B9: 18988.8
A10: 02- Office Supplies and Stationery | B10: 810.06
A11: 05- Pantry | B11: 1602.63
A12: 07- Miscellaneous | B12: 2138.76
A13: 04- Transportation and Vehicle | B13: 1435.77
... A35: Grand Total | B35: 1025870.1

Sheet Cash_in_hand_Jan 2025
A1: Serial Num | B1: Date | C1: Transaction Type | D1: Treasury Type | E1: Category | F1: Sub-Category | G1: Agency | H1: Person In Charge | I1: Vision Desc | J1: Descriptions | K1: Internal document No. | L1: External document No. | M1: Amount | N1: Vat Amount | O1: Vat Eligibility | P1: Remarks
A2: 12600 | B2: 45658 | C2: 01- Paid to: | D2: 02- Electronic Treasury | E2: 02- General Running and Maintenance | F2: 07- Miscellaneous | G2: Shamsin | H2: Mohamed Abdel Moniem | I2: Complementary for Patient | J2: Payment as a Complementray for PT Obaid Family #39290 | K2: 6002 | L2: N/A | M2: 36 | N2: 0
A3: 12398 | B3: 45658 | C3: 01- Paid to: | D3: 01- Main Treasury | E3: 03- Staff Qualification And Education (HR) | F3: 01- Direct Staff Salaries | G3: Lari Exchange | H3: Mohamed Abdel Moniem | I3: Salary FMO Dec2024 | J3: Salary FMO Dec2024 to Dr.Tahoun and Ms.Heba | K3: 6004 | L3: 5.4501013e+15 | M3: 140000
A4: 12399 | B4: 45658 | C4: 01- Paid to: | D4: 01- Main Treasury | E4: 03- Staff Qualification And Education (HR) | F4: 01- Direct Staff Salaries | G4: Lari Exchange | H4: Mohamed Abdel Moniem | I4: Salary FMO Dec2024 | J4: Salary FMO Dec2024 to Razel, Jorylin , Kimberly and Mariam | K4: 6005 | L4: 5.4501013e+15 | M4: 20900
A5: 12400 | B5: 45658 | C5: 01- Paid to: | D5: 01- Main Treasury | E5: 03- Staff Qualification And Education (HR) | F5: 03- External Staff Salaries | G5: Lari Exchange | H5: Mohamed Abdel Moniem | I5: Salary FMO Dec2024 | J5: Salary FMO Dec2024 to External Staff Saber, Saed , Alamghir, Arjun and Algien | K5: 6006 | L5: 5.4501013e+15 | M5: 9000
A6: 12402 | B6: 45658 | C6: 01- Paid to: | D6: 01- Main Treasury | E6: 05- Treasuries Transactions | F6: 01- Treasury Transfer | G6: Adib | H6: Mohamed Abdel Moniem | I6: Bank Transfer | J6: Bank transfer to Electronic Treasury | K6: 6008 | L6: 5.4501013e+15 | M6: 2000
A7: 12349 | B7: 45659 | C7: 01- Paid to: | D7: 02- Electronic Treasury | E7: 01- Equipment and Supply | F7: 01- Consumables / New Invoice Payment | G7: Amazon.ae | H7: Zenneth - Staff | I7: Batteries | J7: Purchase of Batteries | K7: 6131 | L7: 407-4498548-5528300 | M7: 27.1 | N7: 1.29 | O7: Not Eligible
A8: 12602 | B8: 45659 | C8: 01- Paid to: | D8: 01- Main Treasury | E8: 04- Legal and Professionalism | F8: 11- Bank Charges | G8: Lari Exchange | H8: Mohamed Abdel Moniem | I8: Lari Transfer Fee | J8: Payment for Lari Transfer Fees for Dec2024 Salary First Batch | K8: 6007 | L8: 180125796 | M8: 32.55 | N8: 1.55 | O8: Eligible
A9: 12360 | B9: 45659 | C9: 01- Paid to: | D9: 02- Electronic Treasury | E9: 04- Legal and Professionalism | F9: 02- Immigration and Labor | G9: Icp Smart Services | H9: Aasiya Siddiqa | I9: Request Fees, Issue Fees, E-service Fees, Icp Fees, Electronic Payment Fees, | J9: New Visa Issuance - Mysmyle - Moby | K9: 6129 | L9: 7258-1-977694670 | M9: 356.2 | N9: 0
A10: 12361 | B10: 45659 | C10: 01- Paid to: | D10: 02- Electronic Treasury | E10: 04- Legal and Professionalism | F10: 02- Immigration and Labor | G10: Icp Smart Services | H10: Marife Samson | I10: Card Issuance, Electronic Payment Fees, Smart Services Fee, Request Fees, Issue Fees, E-service Fees, Icp Fees, Electronic Payment Fees, | J10: Residency and EID for Genet - Mysmyle (Attached both payments and document files in 1 LPO) | K10: 6130 | L10: 7152-1-903563028 | M10: 761.66 | N10: 0
A11: 12363 | B11: 45659 | C11: 01- Paid to: | D11: 02- Electronic Treasury | E11: 04- Legal and Professionalism | F11: 02- Immigration and Labor | G11: Icp Smart Services | H11: Marife Samson | I11: Request Fees, Issue Fees, E-service Fees, Icp Fees, Electronic Payment Fees, Card Issuance, Electronic Payment Fees, Smart Services Fee, | J11: Residency and EID for Jennifer - Mysmyle ( Both payments and files are attached in 1 LOP only ) | K11: 6132 | L11: 7154-1-908811057 | M11: 761.66 | N11: 0
A12: 12364 | B12: 45659 | C12: 01- Paid to: | D12: 02- Electronic Treasury | E12: 04- Legal and Professionalism | F12: 02- Immigration and Labor | G12: Icp Smart Services | H12: Marife Samson | I12: Request Fees, Issue Fees, E-service Fees, Icp Fees, Electronic Payment Fees, Card Issuance, Electronic Payment Fees, Smart Services Fee, | J12: Residency and EID payment for Aasiya - Mysmyle (Both payments and files are attached in 1 LPO only) | K12: 6133 | L12: 7153-1-785140435 | M12: 761.66 | N12: 0
A13: 12365 | B13: 45659 | C13: 01- Paid to: | D13: 02- Electronic Treasury | E13: 04- Legal and Professionalism | F13: 02- Immigration and Labor | G13: Icp Smart Services | H13: Aasiya Siddiqa | I13: Request Fees, E-service Fees, Icp Fees, Electronic Payment Fees, | J13: Change Status - Mysmyle - Moby | K13: 6134 | L13: 7257-1-698483155 | M13: 660.29 | N13: 0
A14: 12350 | B14: 45660 | C14: 01- Paid to: | D14: 02- Electronic Treasury | E14: 01- Equipment and Supply | F14: 01- Consumables / New Invoice Payment | G14: Amazon.ae | H14: Mohamed Abdel Moniem | I14: Clinic Supplies Purchase | J14: Purchase of Torniquet | K14: 6137 | L14: 407-1150671-9345968 | M14: 16.46
A15: 12351 | B15: 45660 | C15: 01- Paid to: | D15: 02- Electronic Treasury | E15: 01- Equipment and Supply | F15: 01- Consumables / New Invoice Payment | G15: Amazon.ae | H15: Mohamed Abdel Moniem | I15: Lab Tools and Accessories | J15: Purchase of veneers box | K15: 6138 | L15: 407-9908123-5919517 | M15: 70
A16: 12601 | B16: 45660 | C16: 01- Paid to: | D16: 02- Electronic Treasury | E16: 04- Legal and Professionalism | F16: 09- Marketing and Advertisement (PEC) | G16: Facebook | H16: Mohamed Abdel Moniem | I16: Facebook Ads | J16: Payment for facebook ads | K16: 6003 | L16: Qt4qzh4mc2 | M16: 94.37 | N16: 0
A17: 12366 | B17: 45660 | C17: 01- Paid to: | D17: 02- Electronic Treasury | E17: 04- Legal and Professionalism | F17: 02- Immigration and Labor | G17: Icp Smart Services | H17: Marife Samson | I17: Request Fees, E-service Fees, Icp Fees, Electronic Payment Fees, | J17: Residence Visa cancellation under Vision Dental Clinic- Manju Devadasan | K17: 6135 | L17: 7162-1-780862608 | M17: 204.15 | N17: 0
A18: 12616 | B18: 45660 | C18: 01- Paid to: | D18: 01- Main Treasury | E18: 04- Legal and Professionalism | F18: 02- Immigration and Labor | G18: Abu Dhabi Pension Fund | H18: Mohamed Abdel Moniem | I18: Staff Benefits | J18: Payment for Muna Mohamed Retirement Pensions | K18: 6327 | L18: MC2025X322758E | M18: 1300 | N18: 0
A19: 12418 | B19: 45660 | C19: 01- Paid to: | D19: 02- Electronic Treasury | E19: 04- Legal and Professionalism | F19: 04- Departement of health (DOH)-HAAD | G19: Tamm Doh | H19: Aasiya Siddiqa | I19: Doh- License Issuance Fee, Processing Charges, | J19: DOH Facility License Renewal - Vision Dental Clinic (Receipt include DOH application fees. Please Ignore the Application fees 100 AED receipt). Note: Check page 2 of PDF for attachment. | K19: 6136 | L19: 7255-1-209242459 | M19: 23006 | N19: 0
A20: 12352 | B20: 45661 | C20: 01- Paid to: | D20: 02- Electronic Treasury | E20: 01- Equipment and Supply | F20: 01- Consumables / New Invoice Payment | G20: New Al Daman Pharmacy Llc | H20: Mohamed Abdel Moniem | I20: Medicine for Triage | J20: Purchase of RBS Strips | K20: 6141 | L20: 820041 | M20: 80
A21: 12353 | B21: 45661 | C21: 01- Paid to: | D21: 02- Electronic Treasury | E21: 01- Equipment and Supply | F21: 01- Consumables / New Invoice Payment | G21: New Al Daman Pharmacy Llc | H21: Mohamed Abdel Moniem | I21: Medicine for Triage | J21: Purchase of RBS Lancet | K21: 6142 | L21: 820042 | M21: 40
A22: 12354 | B22: 45661 | C22: 01- Paid to: | D22: 02- Electronic Treasury | E22: 02- General Running and Maintenance | F22: 02- Office Supplies and Stationery | G22: Delight Stationery | H22: Mohamed Abdel Moniem | I22: Office Supplies and Stationery | J22: Purchase of Office Supplies | K22: 6143 | L22: CB-25-00154 | M22: 63 | N22: 3 | O22: Eligible
A23: 12355 | B23: 45661 | C23: 01- Paid to: | D23: 02- Electronic Treasury | E23: 01- Equipment and Supply | F23: 01- Consumables / New Invoice Payment | G23: Aster Pharmacy | H23: Mohamed Abdel Moniem | I23: Crash Cart Medicine | J23: Purchase of Crash Cart medicine | K23: 6145 | L23: 1245-124504-1736000537248 | M23: 35.1
A24: 12612 | B24: 45661 | C24: 01- Paid to: | D24: 02- Electronic Treasury | E24: 02- General Running and Maintenance | F24: 05- Pantry | G24: Home Centre | H24: Mohamed Abdel Moniem | I24: Pantry Supplies | J24: Payment for Door Mat | K24: 6144 | L24: 4.0006206e+19 | M24: 99 | N24: 4.71 | O24: Not Eligible
A25: 12367 | B25: 45661 | C25: 01- Paid to: | D25: 02- Electronic Treasury | E25: 04- Legal and Professionalism | F25: 09- Marketing and Advertisement (PEC) | G25: Google | H25: Mohamed Mohamed Elsamanodey | I25: Social Media Ads, | J25: Payment for Social Media ADS | K25: 6139 | L25: 7230-1-697661646 | M25: 1134.09 | N25: 0
A26: 12368 | B26: 45661 | C26: 01- Paid to: | D26: 02- Electronic Treasury | E26: 04- Legal and Professionalism | F26: 09- Marketing and Advertisement (PEC) | G26: Facebook | H26: Mohamed Mohamed Elsamanodey | I26: Facebook Ads, | J26: Payment for Facebook Ads | K26: 6140 | L26: 7229-1-558010850 | M26: 369 | N26: 0
A27: 12322 | B27: 45662 | C27: 01- Paid to: | D27: 05- Reception Treasury | E27: 02- General Running and Maintenance | F27: 07- Miscellaneous | G27: Tea Trend Cafeteria | H27: Zenneth - Staff | I27: Food for Patient | J27: juice for dr tayseer wife | K27: 6101 | L27: 24071 | M27: 10.5 | N27: 0.5 | O27: Not Eligible
A28: 12323 | B28: 45662 | C28: 01- Paid to: | D28: 05- Reception Treasury | E28: 03- Staff Qualification And Education (HR) | F28: 03- External Staff Salaries | G28: Sajed Tahoun | H28: Zenneth - Staff | I28: Salary Advance | J28: Salary advanced of Sajed Tahoun FMO December 2024 | K28: 6102 | L28: NA | M28: 100
A29: 12324 | B29: 45662 | C29: 01- Paid to: | D29: 05- Reception Treasury | E29: 02- General Running and Maintenance | F29: 04- Transportation and Vehicle | G29: Sohag Car Wash Services | H29: Zenneth - Staff | I29: Car Washing | J29: Car Wash payment for company vehicle | K29: 6103 | L29: NA | M29: 30
A30: 12325 | B30: 45662 | C30: 01- Paid to: | D30: 05- Reception Treasury | E30: 02- General Running and Maintenance | F30: 02- Office Supplies and Stationery | G30: Global Digital | H30: Zenneth - Staff | I30: Office Supplies and Stationery | J30: Purchase of Matt Paper Printing | K30: 6104 | L30: 39258 | M30: 21 | N30: 1 | O30: Eligible
A31: 12327 | B31: 45662 | C31: 01- Paid to: | D31: 05- Reception Treasury | E31: 03- Staff Qualification And Education (HR) | F31: 04- Staff Benefits and Bonus | G31: Abu Dhabi Coop | H31: Zenneth - Staff | I31: Staff Benefits | J31: Purchase of Food Supplies for Staff | K31: 6106 | L31: 193011004391 | M31: 1000 | N31: 47.62 | O31: Not Eligible
A32: 12328 | B32: 45662 | C32: 01- Paid to: | D32: 05- Reception Treasury | E32: 02- General Running and Maintenance | F32: 07- Miscellaneous | G32: Abu Dhabi Coop | H32: Zenneth - Staff | I32: Food for Patient | J32: Purchase of Food for Patient 34586 | K32: 6107 | L32: 19201100438222-19201100437382 | M32: 32.5 | N32: 1.55 | O32: Not Eligible
A33: 12329 | B33: 45662 | C33: 01- Paid to: | D33: 05- Reception Treasury | E33: 01- Equipment and Supply | F33: 01- Consumables / New Invoice Payment | G33: ABDU Market LLC | H33: Zenneth - Staff | I33: Cleaning Materials (Gloves & Mop) | J33: Purchase of Gloves | K33: 6108 | L33: 001-186147 | M33: 14 | N33: 0.67 | O33: Not Eligible
A34: 12330 | B34: 45662 | C34: 01- Paid to: | D34: 05- Reception Treasury | E34: 02- General Running and Maintenance | F34: 04- Transportation and Vehicle | G34: National Taxi | H34: Zenneth - Staff | I34: Taxi Fare | J34: Taxi Fare for Chart Collection | K34: 6109 | L34: 8681 | M34: 24
A35: 12331 | B35: 45662 | C35: 01- Paid to: | D35: 05- Reception Treasury | E35: 02- General Running and Maintenance | F35: 01- General Maintenance | G35: Rowad Al Ebtekar | H35: Zenneth - Staff | I35: General Maintenance and fixtures | J35: Payment for Furniture fixing for clinic 3 | K35: 6110 | L35: 408 | M35: 220
A36: 12332 | B36: 45662 | C36: 01- Paid to: | D36: 05- Reception Treasury | E36: 02- General Running and Maintenance | F36: 01- General Maintenance | G36: Continental Electrical Trading Est. | H36: Zenneth - Staff | I36: General Maintenance- Saber | J36: Purchase of Light Bulb | K36: 6111 | L36: 119853 | M36: 31.5 | N36: 1.5 | O36: Not Eligible
A37: 12333 | B37: 45662 | C37: 01- Paid to: | D37: 05- Reception Treasury | E37: 03- Staff Qualification And Education (HR) | F37: 04- Staff Benefits and Bonus | G37: Perfect Zone Automatic Laundry | H37: Zenneth - Staff | I37: Coat Laundry | J37: Payment for Laundry of Dr Coat | K37: 6112 | L37: 9743 | M37: 33.6 | N37: 1.6 | O37: Not Eligible
A38: 12334 | B38: 45662 | C38: 01- Paid to: | D38: 05- Reception Treasury | E38: 02- General Running and Maintenance | F38: 01- General Maintenance | G38: Continental Electrical Trading Est. | H38: Zenneth - Staff | I38: General Maintenance- Saber | J38: Purchase of Light Bulb | K38: 6113 | L38: 119864 | M38: 5.25 | N38: 0.25 | O38: Not Eligible
A39: 12345 | B39: 45662 | C39: 01- Paid to: | D39: 02- Electronic Treasury | E39: 03- Staff Qualification And Education (HR) | F39: 04- Staff Benefits and Bonus | G39: Baqala Golden Tulip | H39: Zenneth - Staff | I39: Top Up for Facility Mobiles | J39: Top up for Ortho Mobile | K39: 6124 | L39: 30951160071 | M39: 52
A40: 12406 | B40: 45662 | C40: 01- Paid to: | D40: 01- Main Treasury | E40: 01- Equipment and Supply | F40: 02- Consumables / Old Invoice Payment | G40: Three Dimensions Me General Trading Llc | H40: Helen Dacayo | I40: 3d Ink Shade Bl, Delivery Charge, | J40: 3D INK Shade | K40: 6020 | L40: 7148-1-137367430-02928-24 | M40: 2126.25 | N40: 101.25 | O40: Eligible
...

Sheet Pivot Movement
A1: In Value | D1: In Units
A2: Row Labels | B2: Sum of Transaction Value | D2: Row Labels | E2: Sum of Quanity
A3: 01- Purchase | B3: 62203.527 | D3: 01- Purchase | E3: 1473
A4: Al Hayat Pharmaceuticals | B4: 3545 | D4: 01- Medical & LAB Devices. Instruments- (DEV) | E4: 71
A5: City Pharmacy Co. WLL | B5: 5087.5 | D5: 06- Hand Instruments (Restorative, Perio, Endo, Implants,Ortho…) | E5: 68
A6: Panacea Synthetic Gas Trading LLC | B6: 690 | D6: 04- Hand Pieces, Scaler Devices & Accessories | E6: 2
A7: Sirona Dental Systems Trading LLC | B7: 1611 | D7: 08- Cssd, Triage, PCI Devices | E7: 1
A8: Saber Mohammed/Elwan Technical Supplies | B8: 850 | D8: 02- Drugs, Needles & Triage- (DRG) | E8: 78
A9: Jackson Trading Co. LLC | B9: 914 | D9: 03- Vital Signs/ Emergency Supplies | E9: 18
A10: Alphamed General Trading LLC | B10: 2060 | D10: 04- Needles & Syringes | E10: 60
A11: Itqan Dental Supply LLC | B11: 591 | D11: 03- Prevention & Control of Infection- (PCI) | E11: 639
A12: Sapling Drug Store | B12: 10500 | D12: 01- Personal Protective Equipment | E12: 320
A13: Bio Link Medical Surgical Equipment & Intruments Trading LLC | B13: 925 | D13: 02- Disinfectants & Lubricants | E13: 13
A14: Everest Medical & Safety Trading | B14: 7402.5304 | D14: 03- General & Waste Management | E14: 214
... A55: Grand Total | B55: -38053.96 | D55: 04- Dental Materials & Supplies- (DMS) | E55: -288.32667
D56: 01- Burs & Stones Tools | E56: -28.3
D57: 02- Nitrous & Oxygen Sedation | E57: -11
D58: 03- Scaling / Gingiva Materials & Supplies | E58: -7.365
D59: 04- Restorative Fillings, Adhesives & Supplies | E59: -34.95
D60: 05- Endodontic Materials & Posts Supplies | E60: -93.666667
D61: 06- Surgical Materials & Supplies | E61: -80.545
D62: 07- Impression Materials & Supplies | E62: -9.5
D63: 08- Bleaching Material & Supplies | E63: -5
D64: 10- Patient Education Printouts & Giveaways | E64: -18
D65: 05- Implants- (IMPL) | E65: -130
D66: 01- Implant Fixtures | E66: -48
D67: 03- Abutments | E67: -20
... D95: Grand Total | E95: 343.57667

Sheet Movement Jan 2025
A1: Movement Date | B1: Transaction Type | C1: Category | D1: Sub-Category | E1: Type | F1: Variant 1 | G1: Variant 2 (If Applicable) | H1: Vision Description (Description understood by VDC users) | I1: Quanity | J1: Unit Of Measure | K1: Vision ID | L1: Item Price (Without Vat) | M1: Item Vat ( If Applicable) | N1: Warranty Certificate | O1: Medication Alerts (For Medcines Only) | P1: Color Classification (For Electronic Devices) | Q1: Expiration / Depreciation Date | R1: Department Ownership | S1: Internal User /Agent Name | T1: Internal User ID | U1: Undertaking Staff ID / Form | V1: Location | W1: Location ID | X1: Location Index | Y1: Incident Report Attached | Z1: PPM Date (For electronic Devices) | AA1: Disposal Forms | AB1: Stock Description (the exact description as per the supplier Invoice) | AC1: Brand / Model | AD1: Supplier Details | AE1: Supplier/Customer Name | AF1: Supplier / Agency represertative | AG1: Supplier / Agency Contact Number | AH1: Financial Grading | AI1: Door Number | AJ1: Buffer Stock (1 clinic usage/ month) | AK1: LPO/IPO Number | AL1: Transaction Value | AM1: Payment Voucher Number | AN1: External Doc Num. | AO1: Invoice Amount | AP1: VAT | AQ1: Total amount | AR1: Amount Paid
A2: 45661 | B2: 01- Purchase | C2: 04- Dental Materials & Supplies- (DMS) | D2: 01- Burs & Stones Tools | E2: Burs | F2: Straight Black Cylinder Round Tip | G2: NA | H2: Straight Black Cylinder Round Tip | I2: 4 | J2: Pkt | K2: D881 SG 1.2 | L2: 60 | M2: NA | N2: NA | O2: NA | P2: NA | Q2: NA | R2: 08- FIN/INV | S2: NA | T2: NA | U2: NA | V2: 32- Main Inventory 1 | W2: NA | X2: 7.4 | Y2: NA | Z2: NA | AA2: NA | AB2: Bur - Diamond Bur #52 - Stoddard | AC2: Stoddard | AD2: Al Hana Medical Equipments | AE2: Al Hana Medical Equipments | AF2: Mahamud | AG2: +971 50 219 8081 | AH2: 02- Reusable | AI2: 7 | AJ2: 1 | AK2: LPO-7168 | AL2: 240 | AM2: - | AN2: 41750 | AO2: 240 | AP2: 12 | AQ2: 252 | AR2: -
A3: 45663 | B3: 01- Purchase | C3: 08- Facility Management & (FMS) | D3: 07- Pantry Supplies | E3: Pantry Supplies | F3: Coffee Powder | G3: NA | H3: Coffee Powder | I3: 1 | J3: Pack | K3: IGDE044 | L3: 90 | M3: NA | N3: NA | O3: NA | P3: NA | Q3: 45901 | R3: 08- FIN/INV | S3: NA | T3: NA | U3: NA | V3: 30- Main Inventory 2 | W3: NA | X3: 8.2 | Y3: NA | Z3: NA | AA3: NA | AB3: Espresso Barista C&B - 1Kg | AC3: DALLMAYR | AD3: Jackson Trading Co. LLC | AE3: Jackson Trading Co. LLC | AF3: Sales | AG3: +971 56 975 6706 | AH3: 01- Consumables | AI3: 8 | AJ3: 1 | AK3: LPO-7166 | AL3: 90 | AM3: - | AN3: AUH-32123 | AO3: 90 | AP3: 4.5 | AQ3: 94.5 | AR3: -
A4: 45663 | B4: 01- Purchase | C4: 04- Dental Materials & Supplies- (DMS) | D4: 04- Restorative Fillings, Adhesives & Supplies | E4: Restorative Fillings | F4: Ceramic Polisher | G4: NA | H4: Ceramic Polisher | I4: 1 | J4: Pcs | K4: K0200-06 | L4: 135 | M4: NA | N4: NA | O4: NA | P4: NA | Q4: NA | R4: 08- FIN/INV | S4: NA | T4: NA | U4: NA | V4: 32- Main Inventory 1 | W4: NA | X4: 8.3 | Y4: NA | Z4: NA | AA4: NA | AB4: Kenda 0200 All Ceramic 2-steps Set 6Pcs F Polish Com | AC4: KENDA | AD4: Hachem Dental Care LLC | AE4: Hachem Dental Care LLC | AF4: Hadi | AG4: +971 52 824 3223 | AH4: 02- Reusable | AI4: 8 | AJ4: 1 | AK4: LPO-7172 | AL4: 135 | AM4: - | AN4: 1000026 | AO4: 135 | AP4: 0 | AQ4: 135 | AR4: 135
A5: 45663 | B5: 01- Purchase | C5: 08- Facility Management & (FMS) | D5: 07- Pantry Supplies | E5: Pantry Supplies | F5: Milk Powder | G5: NA | H5: Milk Powder | I5: 2 | J5: Kilogram | K5: IGDT002 | L5: 60 | M5: NA | N5: NA | O5: NA | P5: NA | Q5: 45901 | R5: 08- FIN/INV | S5: NA | T5: NA | U5: NA | V5: 30- Main Inventory 2 | W5: NA | X5: 8.2 | Y5: NA | Z5: NA | AA5: NA | AB5: Dallmayr Topping | AC5: DALLMAYR | AD5: Jackson Trading Co. LLC | AE5: Jackson Trading Co. LLC | AF5: Sales | AG5: +971 56 975 6706 | AH5: 01- Consumables | AI5: 8 | AJ5: 1 | AK5: LPO-7166 | AL5: 120 | AM5: - | AN5: AUH-32123 | AO5: 120 | AP5: 6 | AQ5: 126 | AR5: -
A6: 45663 | B6: 01- Purchase | C6: 08- Facility Management & (FMS) | D6: 07- Pantry Supplies | E6: Pantry Supplies | F6: Chocolate Powder | G6: NA | H6: Chocolate Powder | I6: 3 | J6: Kilogram | K6: IGDC001 | L6: 50 | M6: NA | N6: NA | O6: NA | P6: NA | Q6: 45901 | R6: 08- FIN/INV | S6: NA | T6: NA | U6: NA | V6: 30- Main Inventory 2 | W6: NA | X6: 8.2 | Y6: NA | Z6: NA | AA6: NA | AB6: Dallmayr Premium Chocolate | AC6: DALLMAYR | AD6: Jackson Trading Co. LLC | AE6: Jackson Trading Co. LLC | AF6: Sales | AG6: +971 56 975 6706 | AH6: 01- Consumables | AI6: 8 | AJ6: 1 | AK6: LPO-7166 | AL6: 150 | AM6: - | AN6: AUH-32123 | AO6: 150 | AP6: 7.5 | AQ6: 157.5 | AR6: -
A7: 45663 | B7: 01- Purchase | C7: 08- Facility Management & (FMS) | D7: 07- Pantry Supplies | E7: Pantry Supplies | F7: Stirrer | G7: NA | H7: Stirrer | I7: 4 | J7: Bundle | K7: IGDT001 | L7: 8 | M7: NA | N7: NA | O7: NA | P7: NA | Q7: NA | R7: 08- FIN/INV | S7: NA | T7: NA | U7: NA | V7: 30- Main Inventory 2 | W7: NA | X7: 8.3 | Y7: NA | Z7: NA | AA7: NA | AB7: Automatic Stirrer 105mm | AC7: DALLMAYR | AD7: Jackson Trading Co. LLC | AE7: Jackson Trading Co. LLC | AF7: Sales | AG7: +971 56 975 6706 | AH7: 01- Consumables | AI7: 8 | AJ7: 1 | AK7: LPO-7166 | AL7: 32 | AM7: - | AN7: AUH-32123 | AO7: 32 | AP7: 1.6 | AQ7: 33.6 | AR7: -
A8: 45664 | B8: 01- Purchase | C8: 04- Dental Materials & Supplies- (DMS) | D8: 05- Endodontic Materials & Posts Supplies | E8: Endodontic Materials | F8: Endo XP Finisher | G8: NA | H8: Endo XP Finisher | I8: 3 | J8: Pack of 3pcs | K8: S1.XB0. 00.0AA .FKG | L8: 240 | M8: NA | N8: NA | O8: NA | P8: NA | Q8: NA | R8: 08- FIN/INV | S8: NA | T8: NA | U8: NA | V8: 32- Main Inventory 1 | W8: NA | X8: 8.4 | Y8: NA | Z8: NA | AA8: NA | AB8: XP Endo Finisher 25mm - S1.XB0.00.0AA.FK G | AC8: FKG | AD8: Dubai Medical Equipment LLC | AE8: Dubai Medical Equipment LLC | AF8: Mr.Islam | AG8: +971 55 167 3454 | AH8: 02- Reusable | AI8: 8 | AJ8: 1 | AK8: LPO-7169 | AL8: 720 | AM8: - | AN8: INV/2025/00092 | AO8: 720 | AP8: 0 | AQ8: 720 | AR8: -
A9: 45664 | B9: 01- Purchase | C9: 06- Laboratory- (LAB) | D9: 07- Lab Drilling / Milling Tools & Accessories | E9: Milling Tools | F9: Lab Diamond Cutting Disc | G9: NA | H9: Diamond Cutting Disc | I9: 6 | J9: Pcs | K9: Disc | L9: 25 | M9: NA | N9: NA | O9: NA | P9: NA | Q9: NA | R9: 08- FIN/INV | S9: NA | T9: NA | U9: NA | V9: 32- Main Inventory 1 | W9: NA | X9: 4.5 | Y9: NA | Z9: NA | AA9: NA | AB9: Diamond Cutting Disc | AC9: NA | AD9: Fala Medical Trading | AE9: Fala Medical Trading | AF9: Peter | AG9: +971 56 9360381 | AH9: 02- Reusable | AI9: 4 | AJ9: 1 | AK9: LPO-7193 | AL9: 150 | AM9: - | AN9: 1499 | AO9: 150 | AP9: 7.5 | AQ9: 157.5 | AR9: -
A10: 45664 | B10: 01- Purchase | C10: 06- Laboratory- (LAB) | D10: 07- Lab Drilling / Milling Tools & Accessories | E10: Milling Tools | F10: Rubber Tornado | G10: NA | H10: Rubber Tornado | I10: 6 | J10: Pcs | K10: TDR0601 | L10: 20.8333 | M10: NA | N10: NA | O10: NA | P10: NA | Q10: NA | R10: 08- FIN/INV | S10: NA | T10: NA | U10: NA | V10: 32- Main Inventory 1 | W10: NA | X10: 4.5 | Y10: NA | Z10: NA | AA10: NA | AB10: Rubber Tornado | AC10: NA | AD10: Fala Medical Trading | AE10: Fala Medical Trading | AF10: Peter | AG10: +971 56 9360381 | AH10: 02- Reusable | AI10: 4 | AJ10: 1 | AK10: LPO-7193 | AL10: 124.9998 | AM10: - | AN10: 1499 | AO10: 124.9998 | AP10: 6.24999 | AQ10: 131.24979 | AR10: -
A11: 45664 | B11: 01- Purchase | C11: 03- Prevention & Control of Infection- (PCI) | D11: 03- General & Waste Management | E11: General Materials | F11: Z Fold Tissue | G11: NA | H11: Z Fold Tissue | I11: 60 | J11: Bundle | K11: DIS142 | L11: 1.6 | M11: NA | N11: NA | O11: NA | P11: NA | Q11: NA | R11: 08- FIN/INV | S11: NA | T11: NA | U11: NA | V11: 30- Main Inventory 2 | W11: NA | X11: 5.2 | Y11: NA | Z11: NA | AA11: NA | AB11: Hand Towel - Z Fold Tissues - 2 Ply (150*16 Pkt) | AC11: NA | AD11: Breath General Trading | AE11: Breath General Trading | AF11: Mustaq | AG11: +971 54 745 6475 | AH11: 01- Consumables | AI11: 5 | AJ11: 1 | AK11: LPO-7171 | AL11: 96 | AM11: - | AN11: VDCL-01 | AO11: 96 | AP11: - | AQ11: 96 | AR11: -
A12: 45665 | B12: 01- Purchase | C12: 06- Laboratory- (LAB) | D12: 03- Dental Blanks | E12: Dental Blanks | F12: Blank - Cercon HT Disk 98mm A3 18 | G12: NA | H12: Blank - Cercon HT Disk 98mm A3 18 | I12: 1 | J12: Disc | K12: 5366091218 | L12: 475 | M12: NA | N12: NA | O12: NA | P12: NA | Q12: 46174 | R12: 08- FIN/INV | S12: NA | T12: NA | U12: NA | V12: 32- Main Inventory 1 | W12: NA | X12: 3.4 | Y12: NA | Z12: NA | AA12: NA | AB12: Blank - Cercon HT Disk 98mm A3 18 | AC12: Dentsply Sirona | AD12: Sirona Dental Systems Trading LLC | AE12: Sirona Dental Systems Trading LLC | AF12: Dr.Marwan | AG12: +971 56 415 6254 | AH12: 01- Consumables | AI12: 3 | AJ12: 1 | AK12: LPO-7126 | AL12: 475 | AM12: - | AN12: INV-00641 | AO12: 475 | AP12: 0 | AQ12: 475 | AR12: -
A13: 45665 | B13: 01- Purchase | C13: 05- Implants- (IMPL) | D13: 04- Implant Impression Tools & Supplies | E13: Implant Impression Tools | F13: Ostell Smartpeg Type 53 | G13: NA | H13: Ostell Smartpeg Type 53 | I13: 5 | J13: Pcs | K13: NA | L13: 80 | M13: NA | N13: NA | O13: NA | P13: NA | Q13: NA | R13: 08- FIN/INV | S13: NA | T13: NA | U13: NA | V13: 32- Main Inventory 1 | W13: NA | X13: 1.3 | Y13: NA | Z13: NA | AA13: NA | AB13: Ostell Smartpeg Type 53 | AC13: Ostell | AD13: Prime Medical Supplies Est. | AE13: Prime Medical Supplies Est. | AF13: Martin | AG13: +971 56 449 6039 | AH13: 02- Reusable | AI13: 1 | AJ13: 1 | AK13: LPO-7184 | AL13: 400 | AM13: - | AN13: 33786 | AO13: 400 | AP13: 0 | AQ13: 400 | AR13: -
A14: 45666 | B14: 01- Purchase | C14: 06- Laboratory- (LAB) | D14: 06- Dental Stone, Stains & Wax | E14: Stains | F14: Gum Composite GHB2 | G14: NA | H14: Gum Composite GHB2 | I14: 1 | J14: Pack | K14: EEP901088 | L14: 165 | M14: NA | N14: NA | O14: NA | P14: NA | Q14: 46357 | R14: 08- FIN/INV | S14: NA | T14: NA | U14: NA | V14: 32- Main Inventory 1 | W14: NA | X14: 3.6 | Y14: NA | Z14: NA | AA14: NA | AB14: Gum Composite - Gradia Plus, Gum Paste , GHB-2 | AC14: NA | AD14: Dubai Medical Equipment LLC | AE14: Dubai Medical Equipment LLC | AF14: Mr.Islam | AG14: +971 55 167 3454 | AH14: 01- Consumables | AI14: 3 | AJ14: 1 | AK14: LPO-7194 | AL14: 165 | AM14: - | AN14: INV/2025/00167 | AO14: 165 | AP14: 0 | AQ14: 165 | AR14: -
A15: 45666 | B15: 01- Purchase | C15: 01- Medical & LAB Devices. Instruments- (DEV) | D15: 08- Cssd, Triage, PCI Devices | E15: PCI Devices | F15: Biological Incubator | G15: NA | H15: Biological Incubator | I15: 1 | J15: Unit | K15: SR-13-EMD-BI-02 | L15: 1500 | M15: 75 | N15: NA | O15: NA | P15: NA | Q15: NA | R15: 08- FIN/INV | S15: NA | T15: NA | U15: NA | V15: 32- Main Inventory 1 | W15: NA | X15: 5.2 | Y15: NA | Z15: NA | AA15: NA | AB15: Biological Incubator | AC15: Medley | AD15: City Pharmacy Co. WLL | AE15: City Pharmacy Co. WLL | AF15: Mr.Anas | AG15: +971 55 244 0493 | AH15: 03- Fixed Assets | AI15: 5 | AJ15: 1 | AK15: LPO-7190 | AL15: 1500 | AM15: - | AN15: 1AINDCP-336343 | AO15: 1500 | AP15: 75 | AQ15: 1575 | AR15: -
A16: 45666 | B16: 01- Purchase | C16: 04- Dental Materials & Supplies- (DMS) | D16: 03- Scaling / Gingiva Materials & Supplies | E16: Gingiva Materials | F16: Retraction Paste | G16: NA | H16: Retraction Paste | I16: 2 | J16: Box of 25 Pcs | K16: 56944 | L16: 350 | M16: NA | N16: NA | O16: NA | P16: NA | Q16: 45925 | R16: 08- FIN/INV | S16: NA | T16: NA | U16: NA | V16: 32- Main Inventory 1 | W16: NA | X16: 7.2 | Y16: NA | Z16: NA | AA16: NA | AB16: Retraction Paste - 3M ESPE Astringent | AC16: 3M ESPE | AD16: Bright Gate Healthcare LLC | AE16: Bright Gate Healthcare LLC | AF16: Sales | AG16: +971 50 622 5639 | AH16: 01- Consumables | AI16: 7 | AJ16: 1 | AK16: LPO-7188 | AL16: 700 | AM16: - | AN16: 18257 | AO16: 700 | AP16: - | AQ16: 700 | AR16: -
A17: 45668 | B17: 01- Purchase | C17: 06- Laboratory- (LAB) | D17: 06- Dental Stone, Stains & Wax | E17: Stains | F17: Gum Composite GHB3 | G17: NA | H17: Gum Composite GHB3 | I17: 1 | J17: Pack | K17: NA | L17: 165 | M17: NA | N17: NA | O17: NA | P17: NA | Q17: 46357 | R17: 08- FIN/INV | S17: NA | T17: NA | U17: NA | V17: 32- Main Inventory 1 | W17: NA | X17: 3.6 | Y17: NA | Z17: NA | AA17: NA | AB17: Gum Composite - Gradia Plus, Gum Paste , GHB-3 | AC17: NA | AD17: Dubai Medical Equipment LLC | AE17: Dubai Medical Equipment LLC | AF17: Mr.Islam | AG17: +971 55 167 3454 | AH17: 01- Consumables | AI17: 3 | AJ17: 1 | AK17: LPO-7194 | AL17: 165 | AM17: - | AN17: INV/2025/00167 | AO17: 165 | AP17: 0 | AQ17: 165 | AR17: -
A18: 45668 | B18: 01- Purchase | C18: 04- Dental Materials & Supplies- (DMS) | D18: 02- Nitrous & Oxygen Sedation | E18: Nitrous Sedation | F18: Nitrous Oxide Refill | G18: NA | H18: Nitrous Oxide Refill | I18: 1 | J18: Cylinder | K18: MI-DMS-NR-01 | L18: 150 | M18: NA | N18: NA | O18: NA | P18: NA | Q18: NA | R18: 08- FIN/INV | S18: NA | T18: NA | U18: NA | V18: 32- Main Inventory 1 | W18: NA | X18: 2.5 | Y18: NA | Z18: NA | AA18: NA | AB18: Nitrous Oxide Refill | AC18: NA | AD18: Panacea Synthetic Gas Trading LLC | AE18: Panacea Synthetic Gas Trading LLC | AF18: Suresh | AG18: +971 52 850 2873 | AH18: 01- Consumables | AI18: 2 | AJ18: 1 | AK18: LPO-7195 | AL18: 150 | AM18: - | AN18: PSGT-0322025 | AO18: 150 | AP18: 7.5 | AQ18: 157.5 | AR18: -
A19: 45668 | B19: 01- Purchase | C19: 04- Dental Materials & Supplies- (DMS) | D19: 02- Nitrous & Oxygen Sedation | E19: Oxygen Sedation | F19: Oxygen Refill | G19: NA | H19: Oxygen Refill | I19: 2 | J19: Cylinder | K19: MI-DMS-OR-01 | L19: 30 | M19: NA | N19: NA | O19: NA | P19: NA | Q19: NA | R19: 08- FIN/INV | S19: NA | T19: NA | U19: NA | V19: 32- Main Inventory 1 | W19: NA | X19: 2.5 | Y19: NA | Z19: NA | AA19: NA | AB19: Oxygen Refill | AC19: NA | AD19: Panacea Synthetic Gas Trading LLC | AE19: Panacea Synthetic Gas Trading LLC | AF19: Suresh | AG19: +971 52 850 2873 | AH19: 01- Consumables | AI19: 2 | AJ19: 1 | AK19: LPO-7195 | AL19: 60 | AM19: - | AN19: PSGT-0322025 | AO19: 60 | AP19: 3 | AQ19: 63 | AR19: -
A20: 45668 | B20: 01- Purchase | C20: 04- Dental Materials & Supplies- (DMS) | D20: 05- Endodontic Materials & Posts Supplies | E20: Endodontic Materials | F20: Rotary Files - Assorted 25mm | G20: NA | H20: Rotary Files - Assorted 25mm | I20: 10 | J20: Pack of 4Pcs | K20: RFA-00025 | L20: 125 | M20: NA | N20: NA | O20: NA | P20: NA | Q20: NA | R20: 08- FIN/INV | S20: NA | T20: NA | U20: NA | V20: 32- Main Inventory 1 | W20: NA | X20: 8.4 | Y20: NA | Z20: NA | AA20: NA | AB20: Rotary Files Assorted 25mm - Smart Carver Kit | AC20: Smart Files | AD20: Ora Tech Medical and Surgical Articles & Requisites Trading LLC | AE20: Ora Tech Medical and Surgical Articles & Requisites Trading LLC | AF20: Amer | AG20: +971 58 567 3445 | AH20: 02- Reusable | AI20: 8 | AJ20: 1 | AK20: LPO-6989 | AL20: 1250 | AM20: - | AN20: CS0S125000008 | AO20: 1250 | AP20: 0 | AQ20: 1250 | AR20: -
A21: 45668 | B21: 01- Purchase | C21: 04- Dental Materials & Supplies- (DMS) | D21: 05- Endodontic Materials & Posts Supplies | E21: Endodontic Materials | F21: Rotary Files - Assorted 31mm | G21: NA | H21: Rotary Files - Assorted 31mm | I21: 10 | J21: Pack of 4Pcs | K21: RFA-00031 | L21: 125 | M21: NA | N21: NA | O21: NA | P21: NA | Q21: NA | R21: 08- FIN/INV | S21: NA | T21: NA | U21: NA | V21: 32- Main Inventory 1 | W21: NA | X21: 8.4 | Y21: NA | Z21: NA | AA21: NA | AB21: Rotary Files Assorted 31mm - Smart Carver Kit | AC21: Smart Files | AD21: Ora Tech Medical and Surgical Articles & Requisites Trading LLC | AE21: Ora Tech Medical and Surgical Articles & Requisites Trading LLC | AF21: Amer | AG21: +971 58 567 3445 | AH21: 02- Reusable | AI21: 8 | AJ21: 1 | AK21: LPO-7189 | AL21: 1250 | AM21: - | AN21: CS0S125000008 | AO21: 1250 | AP21: 0 | AQ21: 1250 | AR21: -
A22: 45670 | B22: 01- Purchase | C22: 02- Drugs, Needles & Triage- (DRG) | D22: 04- Needles & Syringes | E22: Needles | F22: STA Long | G22: NA | H22: STA Long | I22: 1 | J22: Box of 50 Pcs | K22: MILESTA-5050-301 | L22: 549 | M22: NA | N22: NA | O22: NA | P22: NA | Q22: 46350 | R22: 08- FIN/INV | S22: NA | T22: NA | U22: NA | V22: 32- Main Inventory 1 | W22: NA | X22: 5.6 | Y22: NA | Z22: NA | AA22: NA | AB22: Wand STA Handpieces with Needle 30 gauge x 1" | AC22: WAND STA | AD22: Al Hayat Pharmaceuticals | AE22: Al Hayat Pharmaceuticals | AF22: Dr.Noha | AG22: +971 56 367 4713 | AH22: 01- Consumables | AI22: 5 | AJ22: 1 | AK22: LPO-7185 | AL22: 549 | AM22: - | AN22: TCS-202501802 | AO22: 549 | AP22: 27.45 | AQ22: 576.45 | AR22: -
A23: 45670 | B23: 01- Purchase | C23: 02- Drugs, Needles & Triage- (DRG) | D23: 04- Needles & Syringes | E23: Needles | F23: STA Short | G23: NA | H23: STA Short | I23: 1 | J23: Box of 50 Pcs | K23: MILESTA-5050-305 | L23: 549 | M23: NA | N23: NA | O23: NA | P23: NA | Q23: 46715 | R23: 08- FIN/INV | S23: NA | T23: NA | U23: NA | V23: 32- Main Inventory 1 | W23: NA | X23: 5.6 | Y23: NA | Z23: NA | AA23: NA | AB23: Wand STA Handpieces with Needle 30 gauge x 1/2" | AC23: WAND STA | AD23: Al Hayat Pharmaceuticals | AE23: Al Hayat Pharmaceuticals | AF23: Dr.Noha | AG23: +971 56 367 4713 | AH23: 01- Consumables | AI23: 5 | AJ23: 1 | AK23: LPO-7185 | AL23: 549 | AM23: - | AN23: TCS-202501802 | AO23: 549 | AP23: 27.45 | AQ23: 576.45 | AR23: -
A24: 45670 | B24: 01- Purchase | C24: 05- Implants- (IMPL) | D24: 03- Abutments | E24: Abutments | F24: Titanium Abutments | G24: NA | H24: Titanium Abutment Unibase TBC-SV-RP | I24: 2 | J24: Pcs | K24: NA | L24: 176 | M24: NA | N24: NA | O24: NA | P24: NA | Q24: NA | R24: 08- FIN/INV | S24: NA | T24: NA | U24: NA | V24: 30- Main Inventory 2 | W24: NA | X24: 2.4 | Y24: NA | Z24: NA | AA24: NA | AB24: Titanium Abutment Unibase TBC-SV-RP | AC24: NA | AD24: Edison Medical | AE24: Edison Medical | AF24: Dr. Hala Al Atieh | AG24: +971 56 587 8515 | AH24: 01- Consumables | AI24: 2 | AJ24: 4 | AK24: LPO-7224 | AL24: 352 | AM24: - | AN24: AE-25004013399 | AO24: 352 | AP24: - | AQ24: 352 | AR24: -
A25: 45670 | B25: 01- Purchase | C25: 04- Dental Materials & Supplies- (DMS) | D25: 04- Restorative Fillings, Adhesives & Supplies | E25: Adhesives | F25: Adhesive L-Pop 100 | G25: NA | H25: Adhesive L-Pop 100 | I25: 2 | J25: Box of 100 Pcs | K25: 41279 | L25: 1030 | M25: NA | N25: NA | O25: NA | P25: NA | Q25: 45927 | R25: 08- FIN/INV | S25: NA | T25: NA | U25: NA | V25: 32- Main Inventory 1 | W25: NA | X25: 7.3 | Y25: NA | Z25: NA | AA25: NA | AB25: Adhesive - L-Pop - Single Bond 100's - 3M ESPE | AC25: 3M ESPE | AD25: Alphamed General Trading LLC | AE25: Alphamed General Trading LLC | AF25: Dr.Lujian | AG25: +971 56 697 4909 | AH25: 01- Consumables | AI25: 7 | AJ25: 1 | AK25: LPO-7186 | AL25: 2060 | AM25: - | AN25: LB-DXB-6309591 | AO25: 2060 | AP25: - | AQ25: 2060 | AR25: 2060
A26: 45671 | B26: 01- Purchase | C26: 02- Drugs, Needles & Triage- (DRG) | D26: 04- Needles & Syringes | E26: Syringes | F26: Insuline Syringe | G26: NA | H26: Insuline Syringe | I26: 1 | J26: Box of 10packs | K26: INS01 | L26: 22 | M26: NA | N26: NA | O26: NA | P26: NA | Q26: 46837 | R26: 08- FIN/INV | S26: NA | T26: NA | U26: NA | V26: 32- Main Inventory 1 | W26: NA | X26: 6.5 | Y26: NA | Z26: NA | AA26: NA | AB26: Insuline Syringe | AC26: NA | AD26: Everest Medical & Safety Trading | AE26: Everest Medical & Safety Trading | AF26: Mujeeb | AG26: +971 56 683 3107 | AH26: 01- Consumables | AI26: 6 | AJ26: 1 | AK26: LPO-7191 | AL26: 22 | AM26: - | AN26: MS-INV-28421 | AO26: 22 | AP26: 0 | AQ26: 22 | AR26: -
A27: 45671 | B27: 01- Purchase | C27: 04- Dental Materials & Supplies- (DMS) | D27: 03- Scaling / Gingiva Materials & Supplies | E27: Scaling | F27: Prophy Cup | G27: NA | H27: Prophy Cup | I27: 1 | J27: Pack | K27: PROPHYCUP-00001 | L27: 25 | M27: NA | N27: NA | O27: NA | P27: NA | Q27: NA | R27: 08- FIN/INV | S27: NA | T27: NA | U27: NA | V27: 32- Main Inventory 1 | W27: NA | X27: 8.2 | Y27: NA | Z27: NA | AA27: NA | AB27: Prophylaxis Cup - Standard | AC27: ORO | AD27: Everest Medical & Safety Trading | AE27: Everest Medical & Safety Trading | AF27: Mujeeb | AG27: +971 56 683 3107 | AH27: 01- Consumables | AI27: 8 | AJ27: 1 | AK27: LPO-7191 | AL27: 25 | AM27: - | AN27: MS-INV-28421 | AO27: 25 | AP27: 0 | AQ27: 25 | AR27: -
A28: 45671 | B28: 01- Purchase | C28: 03- Prevention & Control of Infection- (PCI) | D28: 04- Wrapping & Protective Materials | E28: Wrapping | F28: Sterilization Pouch 300 | G28: NA | H28: Sterilization Pouch 300 | I28: 1 | J28: Roll | K28: STR-000300 | L28: 130 | M28: NA | N28: NA | O28: NA | P28: NA | Q28: NA | R28: 08- FIN/INV | S28: NA | T28: NA | U28: NA | V28: 30- Main Inventory 2 | W28: NA | X28: 1.4 | Y28: NA | Z28: NA | AA28: NA | AB28: Sterilization Reel - 300x200mt Plain | AC28: MMC | AD28: Everest Medical & Safety Trading | AE28: Everest Medical & Safety Trading | AF28: Mujeeb | AG28: +971 56 683 3107 | AH28: 01- Consumables | AI28: 1 | AJ28: 1 | AK28: LPO-7191 | AL28: 130 | AM28: - | AN28: MS-INV-28421 | AO28: 130 | AP28: 0 | AQ28: 130 | AR28: -
A29: 45671 | B29: 01- Purchase | C29: 04- Dental Materials & Supplies- (DMS) | D29: 04- Restorative Fillings, Adhesives & Supplies | E29: Restorative Fillings | F29: Composite Universal A2 | G29: NA | H29: Composite Universal A2 | I29: 1 | J29: Syringe | K29: 1370A2 | L29: 128 | M29: NA | N29: NA | O29: NA | P29: NA | Q29: 45992 | R29: 08- FIN/INV | S29: NA | T29: NA | U29: NA | V29: 32- Main Inventory 1 | W29: NA | X29: 8.3 | Y29: NA | Z29: NA | AA29: NA | AB29: Universal Restorative - Filtek Z250 Universal Restorative A2 Shade - 3M ESPE | AC29: 3M ESPE | AD29: Everest Medical & Safety Trading | AE29: Everest Medical & Safety Trading | AF29: Mujeeb | AG29: +971 56 683 3107 | AH29: 01- Consumables | AI29: 8 | AJ29: 1 | AK29: LPO-7191 | AL29: 128 | AM29: - | AN29: MS-INV-28421 | AO29: 128 | AP29: 0 | AQ29: 128 | AR29: -
A30: 45671 | B30: 01- Purchase | C30: 03- Prevention & Control of Infection- (PCI) | D30: 04- Wrapping & Protective Materials | E30: Wrapping | F30: Sterilization Pouch 55 | G30: NA | H30: Sterilization Pouch 55 | I30: 1 | J30: Roll | K30: STR-00055 | L30: 28 | M30: NA | N30: NA | O30: NA | P30: NA | Q30: NA | R30: 08- FIN/INV | S30: NA | T30: NA | U30: NA | V30: 30- Main Inventory 2 | W30: NA | X30: 1.4 | Y30: NA | Z30: NA | AA30: NA | AB30: Sterilization Reel - 55x200mt Plain | AC30: MMC | AD30: Everest Medical & Safety Trading | AE30: Everest Medical & Safety Trading | AF30: Mujeeb | AG30: +971 56 683 3107 | AH30: 01- Consumables | AI30: 1 | AJ30: 1 | AK30: LPO-7191 | AL30: 28 | AM30: - | AN30: MS-INV-28421 | AO30: 28 | AP30: 0 | AQ30: 28 | AR30: -
A31: 45671 | B31: 01- Purchase | C31: 04- Dental Materials & Supplies- (DMS) | D31: 05- Endodontic Materials & Posts Supplies | E31: Endodontic Materials | F31: Rubber Dam Sheet | G31: NA | H31: Rubber Dam Sheet | I31: 1 | J31: Pack of 36 Sheets | K31: DL622B-EBSH0 | L31: 32 | M31: NA | N31: NA | O31: NA | P31: NA | Q31: 46572 | R31: 08- FIN/INV | S31: NA | T31: NA | U31: NA | V31: 32- Main Inventory 1 | W31: NA | X31: 8.4 | Y31: NA | Z31: NA | AA31: NA | AB31: Rubber Dam Sheet | AC31: Sanctuary | AD31: Everest Medical & Safety Trading | AE31: Everest Medical & Safety Trading | AF31: Mujeeb | AG31: +971 56 683 3107 | AH31: 01- Consumables | AI31: 8 | AJ31: 1 | AK31: LPO-7191 | AL31: 32 | AM31: - | AN31: MS-INV-28421 | AO31: 32 | AP31: 0 | AQ31: 32 | AR31: -
A32: 45671 | B32: 01- Purchase | C32: 04- Dental Materials & Supplies- (DMS) | D32: 04- Restorative Fillings, Adhesives & Supplies | E32: Restorative Supplies | F32: Supercap 6.3mm | G32: NA | H32: Supercap 6.3mm | I32: 1 | J32: Pack of 50 Pcs | K32: 2181 | L32: 160 | M32: NA | N32: NA | O32: NA | P32: NA | Q32: NA | R32: 08- FIN/INV | S32: NA | T32: NA | U32: NA | V32: 32- Main Inventory 1 | W32: NA | X32: 7.3 | Y32: NA | Z32: NA | AA32: NA | AB32: Matrix Supercap 6.3mm | AC32: KERR | AD32: Everest Medical & Safety Trading | AE32: Everest Medical & Safety Trading | AF32: Mujeeb | AG32: +971 56 683 3107 | AH32: 01- Consumables | AI32: 7 | AJ32: 1 | AK32: LPO-7191 | AL32: 160 | AM32: - | AN32: MS-INV-28421 | AO32: 160 | AP32: 0 | AQ32: 160 | AR32: -
A33: 45671 | B33: 01- Purchase | C33: 04- Dental Materials & Supplies- (DMS) | D33: 07- Impression Materials & Supplies | E33: Impression Materials | F33: Mixing Tip - Light Green | G33: NA | H33: Mixing Tip - Light Green | I33: 1 | J33: Pack | K33: MXTG-00001 | L33: 25 | M33: NA | N33: NA | O33: NA | P33: NA | Q33: NA | R33: 08- FIN/INV | S33: NA | T33: NA | U33: NA | V33: 32- Main Inventory 1 | W33: NA | X33: 8.5 | Y33: NA | Z33: NA | AA33: NA | AB33: Mixing Tip - Light Green | AC33: NEOPRO | AD33: Everest Medical & Safety Trading | AE33: Everest Medical & Safety Trading | AF33: Mujeeb | AG33: +971 56 683 3107 | AH33: 01- Consumables | AI33: 8 | AJ33: 1 | AK33: LPO-7191 | AL33: 25 | AM33: - | AN33: MS-INV-28421 | AO33: 25 | AP33: 0 | AQ33: 25 | AR33: -
A34: 45671 | B34: 01- Purchase | C34: 04- Dental Materials & Supplies- (DMS) | D34: 05- Endodontic Materials & Posts Supplies | E34: Endodontic Materials | F34: K Files | G34: NA | H34: K Files 31-15 | I34: 1 | J34: Pkt | K34: KF-003115 | L34: 6 | M34: NA | N34: NA | O34: NA | P34: NA | Q34: NA | R34: 08- FIN/INV | S34: NA | T34: NA | U34: NA | V34: 32- Main Inventory 1 | W34: NA | X34: 8.4 | Y34: NA | Z34: NA | AA34: NA | AB34: K Files - 31mm #15 | AC34: Mani | AD34: Everest Medical & Safety Trading | AE34: Everest Medical & Safety Trading | AF34: Mujeeb | AG34: +971 56 683 3107 | AH34: 02- Reusable | AI34: 8 | AJ34: 1 | AK34: LPO-7191 | AL34: 6 | AM34: - | AN34: MS-INV-28421 | AO34: 6 | AP34: - | AQ34: 6 | AR34: -
A35: 45671 | B35: 01- Purchase | C35: 04- Dental Materials & Supplies- (DMS) | D35: 08- Bleaching Material & Supplies | E35: Bleaching Material | F35: Zoom Whitening in Office | G35: NA | H35: Chairside Dental Teeth Whitening | I35: 1 | J35: Pack for 2 Patients | K35: DIC/ZME2665 | L35: 800 | M35: NA | N35: NA | O35: NA | P35: NA | Q35: 46387 | R35: 08- FIN/INV | S35: NA | T35: NA | U35: NA | V35: 32- Main Inventory 1 | W35: NA | X35: 7.1 | Y35: NA | Z35: NA | AA35: NA | AB35: Chairside Dental Teeth Whitening - 2 Complete Patient Kits - Philips Zoom | AC35: Philips Zoom | AD35: Al Hayat Pharmaceuticals | AE35: Al Hayat Pharmaceuticals | AF35: Dr.Noha | AG35: +971 56 367 4713 | AH35: 01- Consumables | AI35: 7 | AJ35: 1 | AK35: LPO-7200 | AL35: 800 | AM35: - | AN35: TCS-20252200 | AO35: 800 | AP35: 40 | AQ35: 840 | AR35: -
A36: 45671 | B36: 01- Purchase | C36: 01- Medical & LAB Devices. Instruments- (DEV) | D36: 06- Hand Instruments (Restorative, Perio, Endo, Implants,Ortho…) | E36: Restorative | F36: Mouth Mirror Head | G36: NA | H36: Mouth Mirror Head | I36: 2 | J36: Pack of 12 Pcs | K36: 5462 | L36: 28 | M36: NA | N36: NA | O36: NA | P36: NA | Q36: NA | R36: 08- FIN/INV | S36: NA | T36: NA | U36: NA | V36: 32- Main Inventory 1 | W36: NA | X36: 5.3 | Y36: NA | Z36: NA | AA36: NA | AB36: Mouth Mirror Head | AC36: NA | AD36: Everest Medical & Safety Trading | AE36: Everest Medical & Safety Trading | AF36: Mujeeb | AG36: +971 56 683 3107 | AH36: 02- Reusable | AI36: 5 | AJ36: 1 | AK36: LPO-7191 | AL36: 56 | AM36: - | AN36: MS-INV-28421 | AO36: 56 | AP36: 0 | AQ36: 56 | AR36: -
A37: 45671 | B37: 01- Purchase | C37: 02- Drugs, Needles & Triage- (DRG) | D37: 04- Needles & Syringes | E37: Syringes | F37: Disposable Syringe 20cc | G37: NA | H37: Disposable Syringe 20cc | I37: 2 | J37: Box of 25pcs | K37: DS20CC | L37: 15 | M37: NA | N37: NA | O37: NA | P37: NA | Q37: 46103 | R37: 08- FIN/INV | S37: NA | T37: NA | U37: NA | V37: 32- Main Inventory 1 | W37: NA | X37: 6.5 | Y37: NA | Z37: NA | AA37: NA | AB37: Syringe 20cc | AC37: MEDISOFT | AD37: Everest Medical & Safety Trading | AE37: Everest Medical & Safety Trading | AF37: Mujeeb | AG37: +971 56 683 3107 | AH37: 01- Consumables | AI37: 6 | AJ37: 1 | AK37: LPO-7191 | AL37: 30 | AM37: - | AN37: MS-INV-28421 | AO37: 30 | AP37: 0 | AQ37: 30 | AR37: -
A38: 45671 | B38: 01- Purchase | C38: 04- Dental Materials & Supplies- (DMS) | D38: 04- Restorative Fillings, Adhesives & Supplies | E38: Restorative | F38: Articulating Paper | G38: NA | H38: Articulating Paper | I38: 2 | J38: Pack of 12 Books | K38: AP-00001 | L38: 14 | M38: NA | N38: NA | O38: NA | P38: NA | Q38: NA | R38: 08- FIN/INV | S38: NA | T38: NA | U38: NA | V38: 32- Main Inventory 1 | W38: NA | X38: 7.3 | Y38: NA | Z38: NA | AA38: NA | AB38: Articulating Paper - Ehros - 12 Books - 12 Sheets/Book | AC38: AP | AD38: Everest Medical & Safety Trading | AE38: Everest Medical & Safety Trading | AF38: Mujeeb | AG38: +971 56 683 3107 | AH38: 01- Consumables | AI38: 7 | AJ38: 1 | AK38: LPO-7191 | AL38: 28 | AM38: - | AN38: MS-INV-28421 | AO38: 28 | AP38: 0 | AQ38: 28 | AR38: -
A39: 45671 | B39: 01- Purchase | C39: 04- Dental Materials & Supplies- (DMS) | D39: 05- Endodontic Materials & Posts Supplies | E39: Endodontic Materials | F39: EDTA | G39: NA | H39: EDTA | I39: 2 | J39: Pack of 3 Syringe | K39: 6320002 | L39: 50 | M39: NA | N39: NA | O39: NA | P39: NA | Q39: 45413 | R39: 08- FIN/INV | S39: NA | T39: NA | U39: NA | V39: 32- Main Inventory 1 | W39: NA | X39: 8.4 | Y39: NA | Z39: NA | AA39: NA | AB39: Root Canal Cleanser - Charm EDTA Gel 1.5g | AC39: DENTKIST | AD39: Everest Medical & Safety Trading | AE39: Everest Medical & Safety Trading | AF39: Mujeeb | AG39: +971 56 683 3107 | AH39: 01- Consumables | AI39: 8 | AJ39: 1 | AK39: LPO-7191 | AL39: 100 | AM39: - | AN39: MS-INV-28421 | AO39: 100 | AP39: 0 | AQ39: 100 | AR39: -
A40: 45671 | B40: 01- Purchase | C40: 04- Dental Materials & Supplies- (DMS) | D40: 04- Restorative Fillings, Adhesives & Supplies | E40: Restorative Fillings | F40: Micro Applicator -Regular | G40: NA | H40: Micro Applicator -Regular | I40: 2 | J40: Tube | K40: MAB-00001 | L40: 9 | M40: NA | N40: NA | O40: NA | P40: NA | Q40: NA | R40: 08- FIN/INV | S40: NA | T40: NA | U40: NA | V40: 32- Main Inventory 1 | W40: NA | X40: 7.3 | Y40: NA | Z40: NA | AA40: NA | AB40: Micro Brush Applicator - Regular | AC40: MICRO-B | AD40: Everest Medical & Safety Trading | AE40: Everest Medical & Safety Trading | AF40: Mujeeb | AG40: +971 56 683 3107 | AH40: 01- Consumables | AI40: 7 | AJ40: 1 | AK40: LPO-7191 | AL40: 18 | AM40: - | AN40: MS-INV-28421 | AO40: 18 | AP40: 0 | AQ40: 18 | AR40: -
...

Sheet Salary 12-2024
B1: Salary FMO December 2024 Paid in January
B2: Record Type | C2: Employee Unique ID / 14 DIGITS | D2: Employee Name | E2: Agent ID/ BANK Routing Code | F2: Employee Card No. or IBAN | G2: Pay Start Date | H2: Pay End Date | I2: Days in Periods | J2: Fix Income | K2: Variable Income | L2: Days on Leave | M2: Basic Income | N2: OT | O2: Allowances | P2: Deductions | Q2: Net Salary | R2: Head
B3: SAL | C3: 30411119077489 | D3: CHERIE ANN RUANO | E3: Mashreq Bank PSC | F3: AE730330000019101566507 | G3: 01-12-2024 | H3: 31-121-2024 | I3: 25 | J3: 6000 | K3: =+N3+O3-P3 -> -1000 | L3: 0 | M3: =+J3 -> 6000 | N3: 0 | O3: 0 | P3: 1000 | Q3: =+M3+O3-P3 -> 5000 | R3: indirect | T3: Row Labels | U3: Sum of Net Salary
B4: SAL | C4: 10016078859321 | D4: Manju Devadasan | E4: 600310101 | F4: AE230030011943926920001 | G4: 01-12-2024 | H4: 31-12-2024 | I4: 5 | J4: 7500 | K4: =N4+O4-P4 -> -6000 | L4: 0 | M4: =+J4 -> 7500 | N4: 0 | O4: 0 | P4: 6000 | Q4: =+M4+O4-P4 -> 1500 | R4: Final Settlemt Direct nurse | T4: Doctors Salary | U4: 154008
B5: Final Settlement | C5: 30420059362009 | D5: Ramil Padilla | E5: DIB | F5: AE770240007520145057601 | G5: 01-12-2024 | H5: 31-12-2024 | I5: 4 | J5: 4000 | K5: =N5+O5-P5 -> -3413 | L5: 0 | M5: 4000 | N5: 0 | O5: 0 | P5: =4000-587 -> 3413 | Q5: =+M5+O5-P5 -> 587 | R5: Final Settlemt Direct nurse | T5: External | U5: 9000
B6: Final Settlement | C6: 10016078859321 | D6: Manju Devadasan | E6: 600310101 | F6: AE230030011943926920001 | G6: 01-12-2024 | H6: 31-12-2024 | I6: 8 | J6: 7500 | K6: =N6+O6-P6 -> -5500 | L6: 0 | M6: =+J6 -> 7500 | N6: 0 | O6: 0 | P6: 5500 | Q6: =+M6+O6-P6 -> 2000 | R6: Final Settlemt Direct nurse | T6: Final Settlemt Direct nurse | U6: 4087
B7: SAL | C7: 00105078982517 | D7: MOHAMED ABDEL MONIEM | E7: 600310101 | F7: AE230030013504627820001 | G7: 01-12-2024 | H7: 31-12-2024 | I7: 31 | J7: 3200 | K7: =N7+O7-P7 -> 5800 | L7: 0 | M7: =+J7 -> 3200 | N7: 0 | O7: =2500+1100+2500+1500+1400-3200 -> 5800 | P7: 0 | Q7: =+M7+O7-P7 -> 9000 | R7: External | S7: Saber , Saed , Alamghir , Arjun and Algien External | T7: indirect | U7: 57055
B8: SAL | C8: 00109067045968 | D8: HUSSEIN SALAH AHMED TAHOUN | E8: EMIRATES ISLAMIC BANK PJSC | F8: AE100340003708482640901 | G8: 01-12-2024 | H8: 31-12-2024 | I8: 31 | J8: 120000 | K8: =N8+O8-P8 -> 0 | L8: 0 | M8: 120000 | N8: 0 | O8: 0 | P8: 0 | Q8: =+M8+O8-P8 -> 120000 | R8: Doctors Salary | T8: Nurse Direct | U8: 24400
B9: SAL | C9: 00115028536953 | D9: HEBA HAMDY | E9: ADIB | F9: AE290500000000019267726 | G9: 01-12-2024 | H9: 31-12-2024 | I9: 31 | J9: 20000 | K9: =N9+O9-P9 -> 0 | L9: 0 | M9: =+J9 -> 20000 | N9: 0 | O9: 0 | P9: 0 | Q9: =+M9+O9-P9 -> 20000 | R9: indirect | T9: Grand Total | U9: 248550
B10: SAL | C10: 30424099342516 | D10: Kimberly Ann Natuel | E10: 600310101 | F10: AE100030012150545910001 | G10: 01-12-2024 | H10: 31-12-2024 | I10: 31 | J10: 3000 | K10: =+N10+O10-P10 -> 0 | L10: 0 | M10: 3000 | N10: 0 | O10: 0 | P10: 0 | Q10: =+O10+J10-P10 -> 3000 | R10: indirect
B11: SAL | C11: 30415118637898 | D11: RAZEL DE GUZMAN PEREZ | E11: 302620122 | F11: AE790260001015790005601 | G11: 01-12-2024 | H11: 31-12-2024 | I11: 31 | J11: 7500 | K11: =+N11+O11-P11 -> 0 | L11: 0 | M11: 7500 | N11: 0 | O11: 0 | P11: 0 | Q11: =+O11+J11-P11 -> 7500 | R11: Nurse Direct | T11: Row Labels | U11: Sum of Net Salary
B12: SAL | C12: 30413059492332 | D12: JOERILYN TURALLO JOVE | E12: 803510106 | F12: AE730351426004716443001 | G12: 01-12-2024 | H12: 31-12-2024 | I12: 31 | J12: 6000 | K12: =+N12+O12-P12 -> 0 | L12: 0 | M12: 6000 | N12: 0 | O12: 0 | P12: 0 | Q12: =+O12+J12-P12 -> 6000 | R12: Nurse Direct | T12: Direct | U12: 5500
B13: SAL | C13: 10028069336246 | D13: MARIYAM PULI MOOTIL | E13: ADCB | F13: AE790030013556902910001 | G13: 01-12-2024 | H13: 31-12-2024 | I13: 31 | J13: 4000 | K13: =+N13+O13-P13 -> 400 | L13: 0 | M13: =+J13 -> 4000 | N13: 0 | O13: 400 | P13: 0 | Q13: =+M13+O13-P13 -> 4400 | R13: indirect | T13: Final Settlement Indirect | U13: 3292
B14: SAL | C14: 00404029649957 | D14: MHD ABDULMOHSEN AMEREDDIN ALNABLSI | E14: 405010101 | F14: AE070500000000028637449 | G14: 01-12-2024 | H14: 31-12-2024 | I14: 28 | J14: 7000 | K14: =+N14+O14-P14 -> -500 | L14: 0 | M14: =+J14 -> 7000 | N14: 0 | O14: 0 | P14: 500 | Q14: =+M14+O14-P14 -> 6500 | R14: indirect | T14: indirect | U14: 49073
B15: SAL | C15: 10010089305600 | D15: ANNIE JOHN JOHN JOSEPH | E15: 302620122 | F15: AE850260001015782862801 | G15: 01-12-2024 | H15: 31-12-2024 | I15: 29 | J15: 6000 | K15: =+N15+O15-P15 -> -100 | L15: 0 | M15: =+J15 -> 6000 | N15: 0 | O15: 2400 | P15: 2500 | Q15: =+M15+O15-P15 -> 5900 | R15: Nurse Direct | T15: Grand Total | U15: 57865
B16: SAL | C16: 01023039157178 | D16: SALIM ALI HAMADANI | E16: 804020101 | F16: AE550400008042796185901 | G16: 01-12-2024 | H16: 31-12-2024 | I16: 29 | J16: 17000 | K16: =+N16+O16-P16 -> -992 | L16: 0 | M16: =+J16 -> 17000 | N16: 0 | O16: 0 | P16: 992 | Q16: =+M16+O16-P16 -> 16008 | R16: Doctors Salary
B17: SAL | C17: 30401098916506 | D17: ZENETH SALADO ZAMORA | E17: 600310101 | F17: AE230030011461513910001 | G17: 01-12-2024 | H17: 31-121-2024 | I17: 31 | J17: 5000 | K17: =+N17+O17-P17 -> 0 | L17: 0 | M17: 5000 | N17: 0 | O17: 0 | P17: 0 | Q17: =+O17+J17-P17 -> 5000 | R17: indirect
B18: SAL | C18: 00125019640220 | D18: Ibrahim Abdelkarim | E18: AL HILAL | F18: AE440530000012021710001 | G18: 01-12-2024 | H18: 31-121-2024 | I18: 31 | J18: 6000 | K18: =+N18+O18-P18 -> -1000 | L18: 0 | M18: 6000 | N18: 0 | O18: 0 | P18: 1000 | Q18: =+O18+J18-P18 -> 5000 | R18: Nurse Direct
B19: SAL | C19: 20014037665353 | D19: ASMA BUTT HAROON ZAFAR | E19: 802420101 | F19: AE430240010520243110901 | G19: 01-12-2024 | H19: 31-121-2024 | I19: 31 | J19: 18000 | K19: =+N19+O19-P19 -> 0 | L19: 0 | M19: =+J19 -> 18000 | N19: 0 | O19: 0 | P19: 0 | Q19: =+M19+O19-P19 -> 18000 | R19: Doctors Salary
B20: SAL | C20: 00105078982517 | D20: MOHAMED ABDEL MONIEM | E20: 600310101 | F20: AE230030013504627820001 | G20: 01-12-2024 | H20: 31-121-2024 | I20: 26 | J20: 3200 | K20: =+N20+O20-P20 -> -425 | L20: 0 | M20: 3200 | N20: 0 | O20: 162 | P20: 587 | Q20: =+M20+O20-P20 -> 2775 | R20: indirect
B21: SAL | C21: 30423078946762 | D21: KAE SANDRA ILAGAN GONZALES | E21: 105310101 | F21: AE330530000012756802001 | G21: 01-12-2024 | H21: 31-121-2024 | I21: 31 | J21: 4000 | K21: =+N21+O21-P21 -> 200 | L21: 0 | M21: =+J21 -> 4000 | N21: 0 | O21: 200 | P21: 0 | Q21: =+M21+O21-P21 -> 4200 | R21: indirect
B22: SAL | C22: 30402099983205 | D22: MARIFE SAMSON SOCAO | E22: 600310101 | F22: AE940030012873333910001 | G22: 01-12-2024 | H22: 31-121-2024 | I22: =31-7 -> 24 | J22: 3850 | K22: =+N22+O22-P22 -> -870 | L22: 0 | M22: =+J22 -> 3850 | N22: 0 | O22: 205 | P22: 1075 | Q22: =+M22+O22-P22 -> 2980 | R22: indirect
B23: SAL | C23: 30421029504901 | D23: JOEL MULA ABORITA | E23: 600310101 | F23: AE810030011938003910001 | G23: 01-12-2024 | H23: 31-121-2024 | I23: 31 | J23: 3000 | K23: =+N23+O23-P23 -> 200 | L23: 0 | M23: =+J23 -> 3000 | N23: 0 | O23: 200 | P23: 0 | Q23: =+M23+O23-P23 -> 3200 | R23: indirect
D25: MYSMYLE COMPANY FOR INFORMATION TECHNOLOGY | E25: MOL: 1519899
B26: Record Type | C26: Employee Unique ID / 14 DIGITS | D26: Employee Name | E26: Agent ID/ BANK Routing Code | F26: Employee Card No. or IBAN | G26: Pay Start Date | H26: Pay End Date | I26: Days in Periods | J26: Fix Income | K26: Variable Income | L26: Days on Leave | M26: Basic Income | N26: OT | O26: Allowances | P26: Deductions | Q26: Net Salary | R26: Head
B27: SAL | C27: 00531078232478 | D27: RAMI MOHAMAD ELMAHMOUD | E27: 803510106 | F27: AE640351416005651558001 | G27: 01-12-2024 | H27: 31-12-2024 | I27: 19 | J27: 5000 | K27: =N27+O27-P27 -> -1708 | L27: 0 | M27: =+J27 -> 5000 | N27: 0 | O27: 0 | P27: 1708 | Q27: =+M27+O27-P27 -> 3292 | R27: Final Settlement Indirect
B28: SAL | C28: 40315039258931 | D28: Genet Tesfaye Tumego | E28: ADCB | F28: AE110030013314321820001 | G28: 01-12-2024 | H28: 31-12-2024 | I28: 31 | J28: 1000 | K28: =+O28-P28 -> 0 | L28: 0 | M28: =+J28 -> 1000 | N28: 0 | O28: 0 | P28: 0 | Q28: =+M28+O28-P28 -> 1000 | R28: indirect
B29: SAL | C29: 30413097846043 | D29: MYRNA LANDICHO VILLEGAS | E29: 600310101 | F29: AE250030012535431910001 | G29: 01-12-2024 | H29: 31-12-2024 | I29: 31 | J29: 2700 | K29: =+N29+O29-P29 -> 150 | L29: 0 | M29: =+J29 -> 2700 | N29: 0 | O29: 150 | P29: 0 | Q29: =+M29+O29-P29 -> 2850 | R29: indirect
